Workbook
Name Coeffs_111: Coefficients!$C$6
Name Coeffs_112: Coefficients!$N$6
Name Coeffs_113: Coefficients!$Y$6
Name Coeffs_121: Coefficients!$C$17
Name Coeffs_122: Coefficients!$N$17
Name Coeffs_123: Coefficients!$Y$17
Name Coeffs_131: Coefficients!$C$28
Name Coeffs_132: Coefficients!$N$28
Name Coeffs_133: Coefficients!$Y$28
Name Coeffs_141: Coefficients!$C$39
Name Coeffs_142: Coefficients!$N$39
Name Coeffs_143: Coefficients!$Y$39
Name Coeffs_211: Coefficients!$C$50
Name Coeffs_221: Coefficients!$C$61
Name Coeffs_231: Coefficients!$C$72
Name Coeffs_241: Coefficients!$C$83
Name Coeffs_251: Coefficients!$C$94
Name Family: Coefficients!$AI$9:$AI$10
Name FamSelect: Coefficients!$AJ$8
Name Princeton: Coefficients!$AI$13:$AI$16
Name Sex: Coefficients!$AI$29:$AI$31
Name TypeSelect: Coefficients!$AJ$23
Name UN: Coefficients!$AI$17:$AI$21
Name Variant: Coefficients!$AI$24:$AI$26

Sheet Introduction
A1: Estimation of child mortality using data on children ever born and children surviving - Instructions
A3: This method is described at:
A4: http://demographicestimation.iussp.org/content/indirect-estimation-child-mortality
A6: This spreadsheet estimates child mortality from data on the mean number of children ever born and surviving by age of mother, the duration since first birth, or duration since marriage.
A8: Set input parameters
A9: 1 | B9: Enter the country name and data descriptor in the green cell to the right. | C9: Country | D9: México | F9: Malawi
A11: 2 | B11: Record the date of the inquiry in the green cell to the right. | C11: Census date | D11: 43891 | F11: 39617
A14: 3 | B14: Specify the variant of the model to be fitted. | C14: Variant of method | D14: Age of mother
A17: 4 | B17: Set the mortality parameters for the method in the green cells to the right. | C17: Family of model life tables | D17: Princeton
C18: Mortality pattern | D18: West
C20: Sex | D20: Both
C21: Mean age of childbearing | D21: 28
A23: 5 | B23: Place the mean number of children ever born, tabulated according to the variant of the model in cells B5:B11 of the Method sheet. | C23: =IF(ISNA(VLOOKUP(VALUE(RIGHT(Coefficients!AM5,3)),Coefficients!$AI$34:$AI$50,1,FALSE)),"INVALID SELECTION - Please ensure that your choice of variant; family and pattern are consistent.","")
A25: 6 | B25: Place the mean number of children surviving, tabulated according to the variant of the model in cells C5:C11 of the Method sheet.
A27: Results
B28: Estimates of infant mortality, q(1), and child mortality, q(5), are located in cells L5:M10 of the Method sheet.
B29: Time locations of these estimates are located in cells K5:K10 of the Method sheet.

Sheet Coefficients
A1: BY AGE OF MOTHER | L1: BY DURATION SINCE FIRST BIRTH | W1: BY DURATION SINCE MARRIAGE
C3: Conversion of D into q | H3: Time location | N3: Conversion of D into q | S3: Time location | Y3: Conversion of D into q | AD3: Time location
A4: Princeton - North | N4: Princeton - North | Y4: Princeton - North
A5: Age | B5: x | C5: a(x,j) | D5: b(x,j) | E5: c(x,j) | F5: d(x,j) | H5: e(x,j) | I5: f(x,j) | J5: g(x,j) | L5: Duration | M5: x | N5: a(x,j) | O5: b(x,j) | P5: c(x,j) | S5: e(x,j) | T5: f(x,j) | U5: g(x,j) | W5: Duration | X5: x | Y5: a(x,j) | Z5: b(x,j) | AA5: c(x,j) | AD5: e(x,j) | AE5: f(x,j) | AF5: g(x,j) | AH5: =Introduction!D9&" "&TEXT(YEAR(Introduction!D11),"####") -> México 2020 | AM5: ="Coeffs_"&TEXT(100*AJ8+10*AJ12+AJ23,0) -> Coeffs_141
A6: 15-19 | B6: 1 | C6: 1.1119 | D6: -2.9287 | E6: 0.8507 | H6: 1.0921 | I6: 5.4732 | J6: -1.9672 | L6: 0-4 | M6: 2 | N6: 1.198 | O6: -0.1266 | P6: 0.0038 | S6: 1.71 | T6: 1.07 | U6: -0.35 | W6: 0-4 | X6: 2 | Y6: 1.2615 | Z6: -0.534 | AA6: 0.1252 | AD6: 1.0311 | AE6: 1.3149 | AF6: -0.3282 | AH6: Census date | AJ6: =YEAR(Introduction!D11)+YEARFRAC(DATE(YEAR(Introduction!D11)-1,12,31), Introduction!D11,1) -> 2020.1667 | AM6: 0 | AN6: 1 | AO6: 2 | AP6: 3 | AR6: 5 | AS6: 6 | AT6: 7 | AV6: Metric
A7: 20-24 | B7: 2 | C7: 1.239 | D7: -0.6865 | E7: -0.2745 | H7: 1.3207 | I7: 5.3751 | J7: 0.2133 | L7: 5-9 | M7: 5 | N7: 1.2248 | O7: -0.1919 | P7: -0.087 | S7: 2.16 | T7: 4.36 | U7: 0.12 | W7: 5-9 | X7: 3 | Y7: 1.1957 | Z7: -0.4103 | AA7: -0.093 | AD7: 1.6964 | AE7: 4.5147 | AF7: -0.016 | AL7: 0 | AM7: =OFFSET(INDIRECT($AM$5),$AL7,AM$6) -> 1.1415 | AN7: =OFFSET(INDIRECT($AM$5),$AL7,AN$6) -> -2.707 | AO7: =OFFSET(INDIRECT($AM$5),$AL7,AO$6) -> 0.7663 | AP7: =OFFSET(INDIRECT($AM$5),$AL7,AP$6) -> 0 | AR7: =OFFSET(INDIRECT($AM$5),$AL7,AR$6) -> 1.097 | AS7: =OFFSET(INDIRECT($AM$5),$AL7,AS$6) -> 5.5628 | AT7: =OFFSET(INDIRECT($AM$5),$AL7,AT$6) -> -1.9956 | AV7: =OFFSET(INDIRECT($AM$5),AL7,-1) -> 1
A8: 25-29 | B8: 3 | C8: 1.1884 | D8: 0.0421 | E8: -0.5156 | H8: 1.5996 | I8: 2.6268 | J8: 4.3701 | L8: 10-14 | M8: 5 | N8: 1.2076 | O8: -0.0105 | P8: -0.2911 | S8: 0.66 | T8: 3.5 | U8: 6.65 | W8: 10-14 | X8: 5 | Y8: 1.3067 | Z8: -0.0103 | AA8: -0.4618 | AD8: 1.4285 | AE8: 3.2684 | AF8: 4.4073 | AH8: Model family | AJ8: =MATCH(Introduction!D17,Family,0) -> 1 | AL8: 1 | AM8: =OFFSET(INDIRECT($AM$5),$AL8,AM$6) -> 1.2563 | AN8: =OFFSET(INDIRECT($AM$5),$AL8,AN$6) -> -0.5381 | AO8: =OFFSET(INDIRECT($AM$5),$AL8,AO$6) -> -0.2637 | AP8: =OFFSET(INDIRECT($AM$5),$AL8,AP$6) -> 0 | AR8: =OFFSET(INDIRECT($AM$5),$AL8,AR$6) -> 1.3062 | AS8: =OFFSET(INDIRECT($AM$5),$AL8,AS$6) -> 5.5677 | AT8: =OFFSET(INDIRECT($AM$5),$AL8,AT$6) -> 0.2962 | AV8: =OFFSET(INDIRECT($AM$5),AL8,-1) -> 2
A9: 30-34 | B9: 5 | C9: 1.2046 | D9: 0.3037 | E9: -0.5656 | H9: 2.0779 | I9: -1.7908 | J9: 9.4126 | L9: 15-19 | M9: 5 | N9: 1.203 | O9: 0.0896 | P9: -0.4265 | S9: -1.96 | T9: -0.9 | U9: 17.66 | W9: 15-19 | X9: 10 | Y9: 1.4701 | Z9: 0.1763 | AA9: -0.7268 | AD9: -0.0753 | AE9: -1.08 | AF9: 12.9281 | AI9: Princeton | AL9: 2 | AM9: =OFFSET(INDIRECT($AM$5),$AL9,AM$6) -> 1.1851 | AN9: =OFFSET(INDIRECT($AM$5),$AL9,AN$6) -> 0.0633 | AO9: =OFFSET(INDIRECT($AM$5),$AL9,AO$6) -> -0.4177 | AP9: =OFFSET(INDIRECT($AM$5),$AL9,AP$6) -> 0 | AR9: =OFFSET(INDIRECT($AM$5),$AL9,AR$6) -> 1.5305 | AS9: =OFFSET(INDIRECT($AM$5),$AL9,AS$6) -> 2.5528 | AT9: =OFFSET(INDIRECT($AM$5),$AL9,AT$6) -> 4.8962 | AV9: =OFFSET(INDIRECT($AM$5),AL9,-1) -> 3
A10: 35-39 | B10: 10 | C10: 1.2586 | D10: 0.4236 | E10: -0.5898 | H10: 2.7705 | I10: -7.3403 | J10: 14.9352 | L10: 20-24 | M10: 10 | N10: 1.3292 | O10: 0.1598 | P10: -0.5778 | S10: -3.85 | T10: -6.42 | U10: 28.94 | W10: 20-24 | X10: 15 | Y10: 1.5039 | Z10: 0.0039 | AA10: -0.7071 | AD10: -1.9749 | AE10: -3.4773 | AF10: 21.3318 | AI10: UN | AL10: 3 | AM10: =OFFSET(INDIRECT($AM$5),$AL10,AM$6) -> 1.172 | AN10: =OFFSET(INDIRECT($AM$5),$AL10,AN$6) -> 0.2341 | AO10: =OFFSET(INDIRECT($AM$5),$AL10,AO$6) -> -0.4272 | AP10: =OFFSET(INDIRECT($AM$5),$AL10,AP$6) -> 0 | AR10: =OFFSET(INDIRECT($AM$5),$AL10,AR$6) -> 1.9991 | AS10: =OFFSET(INDIRECT($AM$5),$AL10,AS$6) -> -2.4261 | AT10: =OFFSET(INDIRECT($AM$5),$AL10,AT$6) -> 10.4282 | AV10: =OFFSET(INDIRECT($AM$5),AL10,-1) -> 5
A11: 40-44 | B11: 15 | C11: 1.224 | D11: 0.4222 | E11: -0.5456 | H11: 4.152 | I11: -12.2448 | J11: 19.2349 | W11: 25-29 | X11: 20 | Y11: 1.4798 | Z11: -0.2487 | AA11: -0.5582 | AD11: -2.1888 | AE11: 0.6124 | AF11: 23.9376 | AL11: 4 | AM11: =OFFSET(INDIRECT($AM$5),$AL11,AM$6) -> 1.1865 | AN11: =OFFSET(INDIRECT($AM$5),$AL11,AN$6) -> 0.308 | AO11: =OFFSET(INDIRECT($AM$5),$AL11,AO$6) -> -0.4452 | AP11: =OFFSET(INDIRECT($AM$5),$AL11,AP$6) -> 0 | AR11: =OFFSET(INDIRECT($AM$5),$AL11,AR$6) -> 2.7632 | AS11: =OFFSET(INDIRECT($AM$5),$AL11,AS$6) -> -8.4065 | AT11: =OFFSET(INDIRECT($AM$5),$AL11,AT$6) -> 16.1787 | AV11: =OFFSET(INDIRECT($AM$5),AL11,-1) -> 10
A12: 45-49 | B12: 20 | C12: 1.1772 | D12: 0.3486 | E12: -0.4624 | H12: 6.965 | I12: -13.916 | J12: 19.9542 | AH12: Model pattern | AJ12: =MATCH(Introduction!D18,IF(AJ8=1,Princeton,UN),0) -> 4 | AL12: 5 | AM12: =OFFSET(INDIRECT($AM$5),$AL12,AM$6) -> 1.1746 | AN12: =OFFSET(INDIRECT($AM$5),$AL12,AN$6) -> 0.3314 | AO12: =OFFSET(INDIRECT($AM$5),$AL12,AO$6) -> -0.4537 | AP12: =OFFSET(INDIRECT($AM$5),$AL12,AP$6) -> 0 | AR12: =OFFSET(INDIRECT($AM$5),$AL12,AR$6) -> 4.3468 | AS12: =OFFSET(INDIRECT($AM$5),$AL12,AS$6) -> -13.2436 | AT12: =OFFSET(INDIRECT($AM$5),$AL12,AT$6) -> 20.199 | AV12: =OFFSET(INDIRECT($AM$5),AL12,-1) -> 15
AI13: North | AL13: 6 | AM13: =OFFSET(INDIRECT($AM$5),$AL13,AM$6) -> 1.1639 | AN13: =OFFSET(INDIRECT($AM$5),$AL13,AN$6) -> 0.319 | AO13: =OFFSET(INDIRECT($AM$5),$AL13,AO$6) -> -0.4435 | AP13: =OFFSET(INDIRECT($AM$5),$AL13,AP$6) -> 0 | AR13: =OFFSET(INDIRECT($AM$5),$AL13,AR$6) -> 7.5242 | AS13: =OFFSET(INDIRECT($AM$5),$AL13,AS$6) -> -14.2013 | AT13: =OFFSET(INDIRECT($AM$5),$AL13,AT$6) -> 20.0162 | AV13: =OFFSET(INDIRECT($AM$5),AL13,-1) -> 20
AI14: South
A15: Princeton - South | N15: Princeton - South | Y15: Princeton - South | AI15: East | AM15: Selected LT
A16: Age | B16: x | C16: a(x,j) | D16: b(x,j) | E16: c(x,j) | F16: d(x,j) | H16: e(x,j) | I16: f(x,j) | J16: g(x,j) | L16: Duration | M16: x | N16: a(x,j) | O16: b(x,j) | P16: c(x,j) | S16: e(x,j) | T16: f(x,j) | U16: g(x,j) | W16: Duration | X16: x | Y16: a(x,j) | Z16: b(x,j) | AA16: c(x,j) | AD16: e(x,j) | AE16: f(x,j) | AF16: g(x,j) | AI16: West | AM16: x | AN16: logit l(x)
A17: 15-19 | B17: 1 | C17: 1.0819 | D17: -3.0005 | E17: 0.8689 | H17: 1.09 | I17: 5.4443 | J17: -1.9721 | L17: 0-4 | M17: 2 | N17: 1.1705 | O17: -0.1461 | P17: 0.0051 | S17: 1.68 | T17: 0.96 | U17: -0.32 | W17: 0-4 | X17: 2 | Y17: 1.3103 | Z17: -0.5856 | AA17: 0.1367 | AD17: 1.0202 | AE17: 1.3064 | AF17: -0.3297 | AI17: Latin America | AM17: 0
A18: 20-24 | B18: 2 | C18: 1.2846 | D18: -0.6181 | E18: -0.3024 | H18: 1.3079 | I18: 5.5568 | J18: 0.2021 | L18: 5-9 | M18: 5 | N18: 1.3166 | O18: -0.3157 | P18: -0.0971 | S18: 2.29 | T18: 3.84 | U18: -0.01 | W18: 5-9 | X18: 3 | Y18: 1.2309 | Z18: -0.3463 | AA18: -0.1073 | AD18: 1.6601 | AE18: 4.5105 | AF18: -0.0335 | AI18: Chile | AM18: 1 | AN18: =HLOOKUP(Coefficients!$AJ$8*100+Coefficients!$AJ$12*10+Coefficients!$AJ$28,'Model LTs'!$A$2:$AB$13,5,FALSE) -> -1.2920085
A19: 25-29 | B19: 3 | C19: 1.2223 | D19: 0.0851 | E19: -0.4704 | H19: 1.5173 | I19: 2.6755 | J19: 4.7471 | L19: 10-14 | M19: 5 | N19: 1.2952 | O19: -0.0423 | P19: -0.4295 | S19: 1.19 | T19: 3.45 | U19: 5.41 | W19: 10-14 | X19: 5 | Y19: 1.2774 | Z19: 0.0336 | AA19: -0.3987 | AD19: 1.2146 | AE19: 3.4684 | AF19: 4.9524 | AI19: South Asian | AM19: 2 | AN19: =HLOOKUP(Coefficients!$AJ$8*100+Coefficients!$AJ$12*10+Coefficients!$AJ$28,'Model LTs'!$A$2:$AB$13,6,FALSE) -> -1.199382
A20: 30-34 | B20: 5 | C20: 1.1905 | D20: 0.2631 | E20: -0.4487 | H20: 1.9399 | I20: -2.2739 | J20: 10.3876 | L20: 15-19 | M20: 5 | N20: 1.2836 | O20: 0.1308 | P20: -0.6496 | S20: -1.01 | T20: -0.18 | U20: 15.03 | W20: 15-19 | X20: 10 | Y20: 1.3493 | Z20: 0.1366 | AA20: -0.5403 | AD20: -0.6454 | AE20: -1.6045 | AF20: 14.6773 | AI20: Far East | AM20: 3 | AN20: =HLOOKUP(Coefficients!$AJ$8*100+Coefficients!$AJ$12*10+Coefficients!$AJ$28,'Model LTs'!$A$2:$AB$13,7,FALSE) -> -1.1592413
A21: 35-39 | B21: 10 | C21: 1.1911 | D21: 0.3152 | E21: -0.4291 | H21: 2.6157 | I21: -8.4819 | J21: 16.5153 | L21: 20-24 | M21: 10 | N21: 1.5269 | O21: 0.2659 | P21: -0.9174 | S21: -2.68 | T21: -5.06 | U21: 25.21 | W21: 20-24 | X21: 15 | Y21: 1.3592 | Z21: -0.0315 | AA21: -0.4944 | AD21: -2.9104 | AE21: -4.1352 | AF21: 24.0072 | AI21: General | AM21: 4 | AN21: =HLOOKUP(Coefficients!$AJ$8*100+Coefficients!$AJ$12*10+Coefficients!$AJ$28,'Model LTs'!$A$2:$AB$13,8,FALSE) -> -1.1338485
A22: 40-44 | B22: 15 | C22: 1.1564 | D22: 0.3017 | E22: -0.3958 | H22: 4.0794 | I22: -13.8308 | J22: 21.1866 | W22: 25-29 | X22: 20 | Y22: 1.3532 | Z22: -0.1978 | AA22: -0.4099 | AD22: -3.1641 | AE22: 1.2106 | AF22: 26.3515 | AM22: 5 | AN22: =HLOOKUP(Coefficients!$AJ$8*100+Coefficients!$AJ$12*10+Coefficients!$AJ$28,'Model LTs'!$A$2:$AB$13,9,FALSE) -> -1.1143193
A23: 45-49 | B23: 20 | C23: 1.1307 | D23: 0.2596 | E23: -0.3538 | H23: 7.1796 | I23: -15.388 | J23: 21.7892 | AH23: Model variant | AJ23: =MATCH(Introduction!D14,Variant,0) -> 1 | AM23: 10 | AN23: =HLOOKUP(Coefficients!$AJ$8*100+Coefficients!$AJ$12*10+Coefficients!$AJ$28,'Model LTs'!$A$2:$AB$13,10,FALSE) -> -1.064845
AI24: Age of mother | AM24: 15 | AN24: =HLOOKUP(Coefficients!$AJ$8*100+Coefficients!$AJ$12*10+Coefficients!$AJ$28,'Model LTs'!$A$2:$AB$13,11,FALSE) -> -1.029312
AI25: Duration since first birth | AM25: 20 | AN25: =HLOOKUP(Coefficients!$AJ$8*100+Coefficients!$AJ$12*10+Coefficients!$AJ$28,'Model LTs'!$A$2:$AB$13,12,FALSE) -> -0.97893415
A26: Princeton - East | N26: Princeton - East | Y26: Princeton - East | AI26: Duration since marriage
A27: Age | B27: x | C27: a(x,j) | D27: b(x,j) | E27: c(x,j) | F27: d(x,j) | H27: e(x,j) | I27: f(x,j) | J27: g(x,j) | L27: Duration | M27: x | N27: a(x,j) | O27: b(x,j) | P27: c(x,j) | S27: e(x,j) | T27: f(x,j) | U27: g(x,j) | W27: Duration | X27: x | Y27: a(x,j) | Z27: b(x,j) | AA27: c(x,j) | AD27: e(x,j) | AE27: f(x,j) | AF27: g(x,j)
A28: 15-19 | B28: 1 | C28: 1.1461 | D28: -2.2536 | E28: 0.6259 | H28: 1.0959 | I28: 5.5864 | J28: -1.9949 | L28: 0-4 | M28: 2 | N28: 1.2182 | O28: -0.1809 | P28: 0.0214 | S28: 1.68 | T28: 0.99 | U28: -0.33 | W28: 0-4 | X28: 2 | Y28: 1.2299 | Z28: -0.3998 | AA28: 0.091 | AD28: 1.038 | AE28: 1.4213 | AF28: -0.3545 | AH28: Sex | AJ28: =MATCH(Introduction!D20,Sex,0) -> 3
A29: 20-24 | B29: 2 | C29: 1.2231 | D29: -0.4301 | E29: -0.2245 | H29: 1.2921 | I29: 5.5897 | J29: 0.3631 | L29: 5-9 | M29: 5 | N29: 1.2769 | O29: -0.2268 | P29: -0.1052 | S29: 2.19 | T29: 4.28 | U29: 0.02 | W29: 5-9 | X29: 3 | Y29: 1.1611 | Z29: -0.2451 | AA29: -0.0797 | AD29: 1.6441 | AE29: 4.7042 | AF29: 0.0642 | AI29: Male
A30: 25-29 | B30: 3 | C30: 1.1593 | D30: 0.0581 | E30: -0.3479 | H30: 1.5021 | I30: 2.4692 | J30: 5.0927 | L30: 10-14 | M30: 5 | N30: 1.2731 | O30: 0.0005 | P30: -0.372 | S30: 0.71 | T30: 3.63 | U30: 6.36 | W30: 10-14 | X30: 5 | Y30: 1.2036 | Z30: 0.0171 | AA30: -0.2992 | AD30: 1.1068 | AE30: 3.3032 | AF30: 5.4464 | AI30: Female
A31: 30-34 | B31: 5 | C31: 1.1404 | D31: 0.1991 | E31: -0.3487 | H31: 1.9347 | I31: -2.6419 | J31: 10.8533 | L31: 15-19 | M31: 5 | N31: 1.2585 | O31: 0.1216 | P31: -0.5013 | S31: -1.96 | T31: -0.71 | U31: 17.42 | W31: 15-19 | X31: 10 | Y31: 1.2773 | Z31: 0.1015 | AA31: -0.4276 | AD31: -0.8678 | AE31: -1.9683 | AF31: 15.5187 | AI31: Both
A32: 35-39 | B32: 10 | C32: 1.154 | D32: 0.2511 | E32: -0.3506 | H32: 2.6197 | I32: -8.9693 | J32: 17.0981 | L32: 20-24 | M32: 10 | N32: 1.341 | O32: 0.1749 | P32: -0.5964 | S32: -4.06 | T32: -6.35 | U32: 29.14 | W32: 20-24 | X32: 15 | Y32: 1.3014 | Z32: -0.0219 | AA32: -0.4195 | AD32: -3.2154 | AE32: -4.1123 | AF32: 24.8624
A33: 40-44 | B33: 15 | C33: 1.1336 | D33: 0.2556 | E33: -0.3428 | H33: 4.1317 | I33: -14.355 | J33: 21.8247 | W33: 25-29 | X33: 20 | Y33: 1.316 | Z33: -0.163 | AA33: -0.3751 | AD33: -3.3885 | AE33: 1.6746 | AF33: 26.9798 | AH33: Valid combinations | AJ33: =VLOOKUP(100*AJ8+10*AJ12+AJ23,$AI$34:$AI$50,1,FALSE) -> 141
A34: 45-49 | B34: 20 | C34: 1.1201 | D34: 0.2362 | E34: -0.3268 | H34: 7.3657 | I34: -15.8083 | J34: 22.3005 | AI34: 111
AI35: 121
AI36: 131
A37: Princeton - West | N37: Princeton - West | Y37: Princeton - West | AI37: 141
A38: Age | B38: x | C38: a(x,j) | D38: b(x,j) | E38: c(x,j) | F38: d(x,j) | H38: e(x,j) | I38: f(x,j) | J38: g(x,j) | L38: Duration | M38: x | N38: a(x,j) | O38: b(x,j) | P38: c(x,j) | S38: e(x,j) | T38: f(x,j) | U38: g(x,j) | W38: Duration | X38: x | Y38: a(x,j) | Z38: b(x,j) | AA38: c(x,j) | AD38: e(x,j) | AE38: f(x,j) | AF38: g(x,j) | AI38: 211
A39: 15-19 | B39: 1 | C39: 1.1415 | D39: -2.707 | E39: 0.7663 | H39: 1.097 | I39: 5.5628 | J39: -1.9956 | L39: 0-4 | M39: 2 | N39: 1.2049 | O39: -0.1553 | P39: 0.0135 | S39: 1.7 | T39: 1.03 | U39: -0.34 | W39: 0-4 | X39: 2 | Y39: 1.2584 | Z39: -0.4683 | AA39: 0.108 | AD39: 1.0349 | AE39: 1.3714 | AF39: -0.339 | AI39: 221
A40: 20-24 | B40: 2 | C40: 1.2563 | D40: -0.5381 | E40: -0.2637 | H40: 1.3062 | I40: 5.5677 | J40: 0.2962 | L40: 5-9 | M40: 5 | N40: 1.2573 | O40: -0.2266 | P40: -0.0944 | S40: 2.2 | T40: 4.2 | U40: 0.06 | W40: 5-9 | X40: 3 | Y40: 1.1841 | Z40: -0.3006 | AA40: -0.0892 | AD40: 1.6654 | AE40: 4.4588 | AF40: 0.0233 | AI40: 231
A41: 25-29 | B41: 3 | C41: 1.1851 | D41: 0.0633 | E41: -0.4177 | H41: 1.5305 | I41: 2.5528 | J41: 4.8962 | L41: 10-14 | M41: 5 | N41: 1.2431 | O41: -0.023 | P41: -0.3409 | S41: 0.86 | T41: 3.47 | U41: 6.21 | W41: 10-14 | X41: 5 | Y41: 1.2446 | Z41: 0.0131 | AA41: -0.3555 | AD41: 1.2109 | AE41: 3.3291 | AF41: 5.1402 | AI41: 241
...

Sheet Model LTs
A1: Model LTs | B1: logits with e0 = 60
B2: 111 | C2: 112 | D2: 113 | E2: 121 | F2: 122 | G2: 123 | H2: 131 | I2: 132 | J2: 133 | K2: 141 | L2: 142 | M2: 143 | N2: 211 | O2: 212 | P2: 213 | Q2: 221 | R2: 222 | S2: 223 | T2: 231 | U2: 232 | V2: 233 | W2: 241 | X2: 242 | Y2: 243 | Z2: 251 | AA2: 252 | AB2: 253
B3: Princeton North | E3: Princeton South | H3: Princeton East | K3: Princeton West | N3: UN Latin American | Q3: UN Chilean | T3: UN South Asian | W3: UN Far Eastern | Z3: UN General
A4: x | B4: Males | C4: Females | D4: Combined | E4: Males | F4: Females | G4: Combined | H4: Males | I4: Females | J4: Combined | K4: Males | L4: Females | M4: Combined | N4: Males | O4: Females | P4: Combined | Q4: Males | R4: Females | S4: Combined | T4: Males | U4: Females | V4: Combined | W4: Males | X4: Females | Y4: Combined | Z4: Males | AA4: Females | AB4: Combined
A5: 0
A6: 1 | B6: -1.3391919 | C6: -1.3205377 | D6: -1.3300167 | E6: -1.149543 | F6: -1.1287565 | G6: -1.1393153 | H6: -1.1995667 | I6: -1.1590577 | J6: -1.1794669 | K6: -1.3008883 | L6: -1.2828283 | M6: -1.2920085 | N6: -1.2244025 | O6: -1.2375303 | P6: -1.23077 | Q6: -1.1881811 | R6: -1.1106269 | S6: -1.149121 | T6: -1.1633365 | U6: -1.1378733 | V6: -1.1507829 | W6: -1.4833929 | X6: -1.3772257 | Y6: -1.4290934 | Z6: -1.2808738 | AA6: -1.2702343 | AB6: -1.2756596
A7: 2 | B7: -1.2482714 | C7: -1.2060903 | D7: -1.2273209 | E7: -1.0529219 | F7: -1.0009991 | G7: -1.0270731 | H7: -1.1377254 | I7: -1.073353 | J7: -1.1054932 | K7: -1.2215537 | L7: -1.1769512 | M7: -1.199382 | N7: -1.1230472 | O7: -1.1005761 | P7: -1.1119841 | Q7: -1.1426713 | R7: -1.0454 | S7: -1.0933348 | T7: -1.0463869 | U7: -1.0078054 | V7: -1.0272792 | W7: -1.4168729 | X7: -1.2912754 | Y7: -1.3521595 | Z7: -1.1994286 | AA7: -1.1587987 | AB7: -1.1792678
A8: 3 | B8: -1.1910199 | C8: -1.1415199 | D8: -1.1663695 | E8: -1.0116418 | F8: -0.94932383 | G8: -0.98051169 | H8: -1.1122189 | I8: -1.0396889 | J8: -1.0757977 | K8: -1.1859677 | L8: -1.1323859 | M8: -1.1592413 | N8: -1.0763916 | O8: -1.039815 | P8: -1.0582869 | Q8: -1.1204664 | R8: -1.0161031 | S8: -1.0674115 | T8: -0.99614964 | U8: -0.95267015 | V8: -0.97458547 | W8: -1.3824459 | X8: -1.2510803 | Y8: -1.3146345 | Z8: -1.1601037 | AA8: -1.1075443 | AB8: -1.1339041
A9: 4 | B9: -1.1495156 | C9: -1.0955047 | D9: -1.1225794 | E9: -0.99004099 | F9: -0.92335584 | G9: -0.95668616 | H9: -1.0959154 | I9: -1.0182341 | J9: -1.0568391 | K9: -1.1622355 | L9: -1.1053872 | M9: -1.1338485 | N9: -1.0483131 | O9: -1.0046334 | P9: -1.0266376 | Q9: -1.1064494 | R9: -0.99875 | S9: -1.0516453 | T9: -0.9677394 | U9: -0.92208657 | V9: -0.94508558 | W9: -1.3597145 | X9: -1.2265312 | Y9: -1.2909394 | Z9: -1.1355662 | AA9: -1.0767437 | AB9: -1.1061781
A10: 5 | B10: -1.1185632 | C10: -1.0613253 | D10: -1.0899898 | E10: -0.97803105 | F10: -0.90879111 | G10: -0.94337274 | H10: -1.0839282 | I10: -1.0034528 | J10: -1.0434107 | K10: -1.1443837 | L10: -1.0842444 | M10: -1.1143193 | N10: -1.0292629 | O10: -0.98147967 | P10: -1.0055181 | Q10: -1.0965956 | R10: -0.98713579 | S10: -1.0408706 | T10: -0.94947888 | U10: -0.90273095 | V10: -0.92627697 | W10: -1.3430952 | X10: -1.2095785 | Y10: -1.2741583 | Z10: -1.1183427 | AA10: -1.0557703 | AB10: -1.0870409
A11: 10 | B11: -1.0393563 | C11: -0.97867737 | D11: -1.0090526 | E11: -0.94784308 | F11: -0.87426675 | G11: -0.91097597 | H11: -1.0472539 | I11: -0.96210277 | J11: -1.0043335 | K11: -1.0968312 | L11: -1.0329082 | M11: -1.064845 | N11: -0.98369901 | O11: -0.93040264 | P11: -0.95717334 | Q11: -1.071048 | R11: -0.96012757 | S11: -1.0145804 | T11: -0.91071239 | U11: -0.86341317 | V11: -0.88724264 | W11: -1.2967451 | X11: -1.1678086 | Y11: -1.2303496 | Z11: -1.0743949 | AA11: -1.0059691 | AB11: -1.0401061
A12: 15 | B12: -0.99810318 | C12: -0.93456379 | D12: -0.96635457 | E12: -0.92724295 | F12: -0.85272015 | G12: -0.88990311 | H12: -1.0232405 | I12: -0.93688771 | J12: -0.97971407 | K12: -1.0631132 | L12: -0.99562585 | M12: -1.029312 | N12: -0.95845256 | O12: -0.90544375 | P12: -0.93208089 | Q12: -1.0502865 | R12: -0.93957838 | S12: -0.9939579 | T12: -0.89415624 | U12: -0.84720718 | V12: -0.87086768 | W12: -1.2584277 | X12: -1.1373287 | Y12: -1.1963047 | Z12: -1.0466409 | AA12: -0.97788284 | AB12: -1.0121946
A13: 20 | B13: -0.94163339 | C13: -0.88577608 | D13: -0.91382222 | E13: -0.89806981 | F13: -0.82207222 | G13: -0.8599929 | H13: -0.98210627 | I13: -0.90144694 | J13: -0.94156372 | K13: -1.0130423 | L13: -0.94491044 | M13: -0.97893415 | N13: -0.92315127 | O13: -0.87353504 | P13: -0.89850801 | Q13: -1.015086 | R13: -0.90716031 | S13: -0.96027266 | T13: -0.87450043 | U13: -0.82539225 | V13: -0.85012871 | W13: -1.2020972 | X13: -1.0804887 | Y13: -1.1397671 | Z13: -1.0066774 | AA13: -0.93810587 | AB13: -0.97234684

Sheet Decrementos Múltiples
B2: Hombres, 2019
B3: Age x | C3: n | D3: nDx | E3: nDxi | I3: nqx | K3: e0 | M3: nqx_i | O3: ndx_i | Q3: L | R3: T | S3: e0_i | T3: diff
B4: 0 | C4: 1 | D4: ='Defunciones generales'!D21 -> 694 | E4: =Homicidios!D553 -> 0 | F4: =(D4-E4)/D4 -> 1 | G4: =LT!G2 -> 100000 | H4: =1-LT!E2 -> 0.97946153 | I4: =1-H4 -> 0.020538474 | J4: =LT!F2 -> 0.1011621 | K4: =LT!K2 -> 71.491883 | L4: =H4^F4 -> 0.97946153 | M4: =1-L4 -> 0.020538474 | N4: 100000 | O4: =N4*M4 -> 2053.8474 | P4: =C4+(F4*(I4/M4)*(J4-C4)) -> 0.1011621 | Q4: =(C4*N5)+(P4*O4) -> 98153.924 | R4: =R5+Q4 -> 7219395.4 | S4: =R4/N4 -> 72.193954 | T4: =S4-K4 -> 0.70207082
B5: 1 | C5: 4 | D5: ='Defunciones generales'!D22 -> 107 | E5: =Homicidios!D554 -> 3 | F5: =(D5-E5)/D5 -> 0.97196262 | G5: =LT!G3 -> 97946.15 | H5: =1-LT!E3 -> 0.9966119 | I5: =1-H5 -> 0.003388104 | J5: =LT!F3 -> 1.5920759 | K5: =LT!K3 -> 71.988885 | L5: =H5^F5 -> 0.99670673 | M5: =1-L5 -> 0.003293267 | N5: =N4*L4 -> 97946.153 | O5: =N5*M5 -> 322.56283 | P5: =C5+(F5*(I5/M5)*(J5-C5)) -> 1.5921904 | Q5: =(C5*N6)+(P5*O5) -> 391007.94 | R5: =R6+Q5 -> 7121241.5 | S5: =R5/N5 -> 72.705678 | T5: =S5-K5 -> 0.71679326 | V5: Número de años que se espera que viva un hombre de 0 años hasta llegar a los 85 años.
B6: 5 | C6: 5 | D6: ='Defunciones generales'!D23 -> 56 | E6: =Homicidios!D555 -> 0 | F6: =(D6-E6)/D6 -> 1 | G6: =LT!G4 -> 97614.3 | H6: =1-LT!E4 -> 0.99777863 | I6: =1-H6 -> 0.002221371 | J6: =LT!F4 -> 2.5 | K6: =LT!K4 -> 68.228208 | L6: =H6^F6 -> 0.99777863 | M6: =1-L6 -> 0.002221371 | N6: =N5*L5 -> 97623.59 | O6: =N6*M6 -> 216.85821 | P6: =C6+(F6*(I6/M6)*(J6-C6)) -> 2.5 | Q6: =(C6*N7)+(P6*O6) -> 487575.8 | R6: =R7+Q6 -> 6730233.5 | S6: =R6/N6 -> 68.940648 | T6: =S6-K6 -> 0.71243978
B7: 10 | C7: 5 | D7: ='Defunciones generales'!D24 -> 88 | E7: =Homicidios!D556 -> 6 | F7: =(D7-E7)/D7 -> 0.93181818 | G7: =LT!G5 -> 97397.46 | H7: =1-LT!E5 -> 0.99793647 | I7: =1-H7 -> 0.002063526 | J7: =LT!F5 -> 2.5 | K7: =LT!K5 -> 63.37454 | L7: =H7^F7 -> 0.99807703 | M7: =1-L7 -> 0.0019229664 | N7: =N6*L6 -> 97406.732 | O7: =N7*M7 -> 187.30987 | P7: =(((-5/24)*O6)+((2.5)*O7)+((5/24)*O8))/O7 -> 2.845681 | Q7: =(C7*N8)+(P7*O7) -> 486630.13 | R7: =R8+Q7 -> 6242657.7 | S7: =R7/N7 -> 64.088566 | T7: =S7-K7 -> 0.71402569
B8: 15 | C8: 5 | D8: ='Defunciones generales'!D25 -> 290 | E8: =Homicidios!D557 -> 54 | F8: =(D8-E8)/D8 -> 0.8137931 | G8: =LT!G6 -> 97196.48 | H8: =1-LT!E6 -> 0.9933348 | I8: =1-H8 -> 0.006665203 | J8: =LT!F6 -> 2.5 | K8: =LT!K6 -> 58.500416 | L8: =H8^F8 -> 0.99457253 | M8: =1-L8 -> 0.0054274711 | N8: =N7*L7 -> 97219.422 | O8: =N8*M8 -> 527.6556 | P8: =(((-5/24)*O7)+((2.5)*O8)+((5/24)*O9))/O8 -> 2.6612903 | Q8: =(C8*N9)+(P8*O8) -> 484863.08 | R8: =R9+Q8 -> 5756027.6 | S8: =R8/N8 -> 59.206561 | T8: =S8-K8 -> 0.7061446 | V8: Sin COVID | W8: Con COVID
B9: 20 | C9: 5 | D9: ='Defunciones generales'!D26 -> 561 | E9: =Homicidios!D558 -> 168 | F9: =(D9-E9)/D9 -> 0.70053476 | G9: =LT!G7 -> 96548.65 | H9: =1-LT!E7 -> 0.99121542 | I9: =1-H9 -> 0.008784577 | J9: =LT!F7 -> 2.5 | K9: =LT!K7 -> 53.876174 | L9: =H9^F9 -> 0.99383797 | M9: =1-L9 -> 0.006162027 | N9: =N8*L8 -> 96691.766 | O9: =N9*M9 -> 595.81727 | P9: =(((-5/24)*O8)+((2.5)*O9)+((5/24)*O10))/O9 -> 2.5579348 | Q9: =(C9*N10)+(P9*O9) -> 482003.81 | R9: =R10+Q9 -> 5271164.5 | S9: =R9/N9 -> 54.515133 | T9: =S9-K9 -> 0.63895919 | V9: =([1]TV!M53-[1]TV!M71)/[1]TV!J53 -> 66.401396 | W9: =(R4-R22)/N4 -> 71.054309
B10: 25 | C10: 5 | D10: ='Defunciones generales'!D27 -> 745 | E10: =Homicidios!D559 -> 190 | F10: =(D10-E10)/D10 -> 0.74496644 | G10: =LT!G8 -> 95700.51 | H10: =1-LT!E8 -> 0.99032681 | I10: =1-H10 -> 0.009673193 | J10: =LT!F8 -> 2.5 | K10: =LT!K8 -> 49.331492 | L10: =H10^F10 -> 0.99278487 | M10: =1-L10 -> 0.0072151292 | N10: =N9*L9 -> 96095.949 | O10: =N10*M10 -> 693.34468 | P10: =(((-5/24)*O9)+((2.5)*O10)+((5/24)*O11))/O10 -> 2.5841753 | Q10: =(C10*N11)+(P10*O10) -> 478804.74 | R10: =R11+Q10 -> 4789160.7 | S10: =R10/N10 -> 49.83728 | T10: =S10-K10 -> 0.50578792 | V10: Diff | W10: =W9-V9 -> 4.6529127
B11: 30 | C11: 5 | D11: ='Defunciones generales'!D28 -> 866 | E11: =Homicidios!D560 -> 173 | F11: =(D11-E11)/D11 -> 0.80023095 | G11: =LT!G9 -> 94774.78 | H11: =1-LT!E9 -> 0.98853938 | I11: =1-H11 -> 0.01146062 | J11: =LT!F9 -> 2.5 | K11: =LT!K9 -> 44.788927 | L11: =H11^F11 -> 0.99081831 | M11: =1-L11 -> 0.0091816898 | N11: =N10*L10 -> 95402.604 | O11: =N11*M11 -> 875.95712 | P11: =(((-5/24)*O10)+((2.5)*O11)+((5/24)*O12))/O11 -> 2.610564 | Q11: =(C11*N12)+(P11*O11) -> 474919.98 | R11: =R12+Q11 -> 4310356 | S11: =R11/N11 -> 45.180695 | T11: =S11-K11 -> 0.39176796
B12: 35 | C12: 5 | D12: ='Defunciones generales'!D29 -> 962 | E12: =Homicidios!D561 -> 142 | F12: =(D12-E12)/D12 -> 0.85239085 | G12: =LT!G10 -> 93688.6 | H12: =1-LT!E10 -> 0.98564061 | I12: =1-H12 -> 0.014359389 | J12: =LT!F10 -> 2.5 | K12: =LT!K10 -> 40.279203 | L12: =H12^F12 -> 0.98774714 | M12: =1-L12 -> 0.012252855 | N12: =N11*L11 -> 94526.647 | O12: =N12*M12 -> 1158.2213 | P12: =(((-5/24)*O11)+((2.5)*O12)+((5/24)*O13))/O12 -> 2.6296464 | Q12: =(C12*N13)+(P12*O12) -> 469887.84 | R12: =R13+Q12 -> 3835436 | S12: =R12/N12 -> 40.575183 | T12: =S12-K12 -> 0.29597976
B13: 40 | C13: 5 | D13: ='Defunciones generales'!D30 -> 1209 | E13: =Homicidios!D562 -> 110 | F13: =(D13-E13)/D13 -> 0.90901572 | G13: =LT!G11 -> 92343.29 | H13: =1-LT!E11 -> 0.9812032 | I13: =1-H13 -> 0.018796801 | J13: =LT!F11 -> 2.5 | K13: =LT!K11 -> 35.829593 | L13: =H13^F13 -> 0.9828987 | M13: =1-L13 -> 0.017101299 | N13: =N12*L12 -> 93368.426 | O13: =N13*M13 -> 1596.7214 | P13: =(((-5/24)*O12)+((2.5)*O13)+((5/24)*O14))/O13 -> 2.6173755 | Q13: =(C13*N14)+(P13*O13) -> 463037.74 | R13: =R14+Q13 -> 3365548.1 | S13: =R13/N13 -> 36.045891 | T13: =S13-K13 -> 0.21629845
B14: 45 | C14: 5 | D14: ='Defunciones generales'!D31 -> 1680 | E14: =Homicidios!D563 -> 100 | F14: =(D14-E14)/D14 -> 0.94047619 | G14: =LT!G12 -> 90607.53 | H14: =1-LT!E12 -> 0.97617462 | I14: =1-H14 -> 0.023825383 | J14: =LT!F12 -> 2.5 | K14: =LT!K12 -> 31.468084 | L14: =H14^F14 -> 0.97757677 | M14: =1-L14 -> 0.022423229 | N14: =N13*L13 -> 91771.704 | O14: =N14*M14 -> 2057.818 | P14: =(((-5/24)*O13)+((2.5)*O14)+((5/24)*O15))/O14 -> 2.6298408 | Q14: =(C14*N15)+(P14*O14) -> 453981.17 | R14: =R15+Q14 -> 2902510.4 | S14: =R14/N14 -> 31.627509 | T14: =S14-K14 -> 0.15942492
B15: 50 | C15: 5 | D15: ='Defunciones generales'!D32 -> 2027 | E15: =Homicidios!D564 -> 52 | F15: =(D15-E15)/D15 -> 0.97434632 | G15: =LT!G13 -> 88448.77 | H15: =1-LT!E13 -> 0.96707563 | I15: =1-H15 -> 0.032924369 | J15: =LT!F13 -> 2.5 | K15: =LT!K13 -> 27.175105 | L15: =H15^F15 -> 0.96790656 | M15: =1-L15 -> 0.032093441 | N15: =N14*L14 -> 89713.886 | O15: =N15*M15 -> 2879.2273 | P15: =(((-5/24)*O14)+((2.5)*O15)+((5/24)*O16))/O15 -> 2.6343802 | Q15: =(C15*N16)+(P15*O15) -> 441758.27 | R15: =R16+Q15 -> 2448529.2 | S15: =R15/N15 -> 27.292645 | T15: =S15-K15 -> 0.11753978
B16: 55 | C16: 5 | D16: ='Defunciones generales'!D33 -> 2511 | E16: =Homicidios!D565 -> 29 | F16: =(D16-E16)/D16 -> 0.98845082 | G16: =LT!G14 -> 85536.65 | H16: =1-LT!E14 -> 0.95439983 | I16: =1-H16 -> 0.045600168 | J16: =LT!F14 -> 2.5 | K16: =LT!K14 -> 23.015176 | L16: =H16^F16 -> 0.95491442 | M16: =1-L16 -> 0.045085579 | N16: =N15*L15 -> 86834.659 | O16: =N16*M16 -> 3914.9909 | P16: =(((-5/24)*O15)+((2.5)*O16)+((5/24)*O17))/O16 -> 2.6638986 | Q16: =(C16*N17)+(P16*O16) -> 425027.48 | R16: =R17+Q16 -> 2006771 | S16: =R16/N16 -> 23.110253 | T16: =S16-K16 -> 0.095077205
B17: 60 | C17: 5 | D17: ='Defunciones generales'!D34 -> 3034 | E17: =Homicidios!D566 -> 24 | F17: =(D17-E17)/D17 -> 0.99208965 | G17: =LT!G15 -> 81636.17 | H17: =1-LT!E15 -> 0.92758107 | I17: =1-H17 -> 0.072418931 | J17: =LT!F15 -> 2.5 | K17: =LT!K15 -> 18.995368 | L17: =H17^F17 -> 0.92813283 | M17: =1-L17 -> 0.071867171 | N17: =N16*L16 -> 82919.668 | O17: =N17*M17 -> 5959.2019 | P17: =(((-5/24)*O16)+((2.5)*O17)+((5/24)*O18))/O17 -> 2.6698426 | Q17: =(C17*N18)+(P17*O17) -> 400712.46 | R17: =R18+Q17 -> 1581743.5 | S17: =R17/N17 -> 19.075613 | T17: =S17-K17 -> 0.080244734
B18: 65 | C18: 5 | D18: ='Defunciones generales'!D35 -> 3246 | E18: =Homicidios!D567 -> 20 | F18: =(D18-E18)/D18 -> 0.99383857 | G18: =LT!G16 -> 75724.16 | H18: =1-LT!E16 -> 0.88533926 | I18: =1-H18 -> 0.11466074 | J18: =LT!F16 -> 2.5 | K18: =LT!K16 -> 15.283209 | L18: =H18^F18 -> 0.88600384 | M18: =1-L18 -> 0.11399616 | N18: =N17*L17 -> 76960.466 | O18: =N18*M18 -> 8773.1977 | P18: =(((-5/24)*O17)+((2.5)*O18)+((5/24)*O19))/O18 -> 2.6646337 | Q18: =(C18*N19)+(P18*O18) -> 364313.7 | R18: =R19+Q18 -> 1181031 | S18: =R18/N18 -> 15.345944 | T18: =S18-K18 -> 0.062735137
B19: 70 | C19: 5 | D19: ='Defunciones generales'!D36 -> 3323 | E19: =Homicidios!D568 -> 3 | F19: =(D19-E19)/D19 -> 0.9990972 | G19: =LT!G17 -> 67041.57 | H19: =1-LT!E17 -> 0.81077668 | I19: =1-H19 -> 0.18922332 | J19: =LT!F17 -> 2.5 | K19: =LT!K17 -> 11.938769 | L19: =H19^F19 -> 0.81093023 | M19: =1-L19 -> 0.18906977 | N19: =N18*L18 -> 68187.268 | O19: =N19*M19 -> 12892.151 | P19: =(((-5/24)*O18)+((2.5)*O19)+((5/24)*O20))/O19 -> 2.6162448 | Q19: =(C19*N20)+(P19*O19) -> 310204.61 | R19: =R20+Q19 -> 816717.31 | S19: =R19/N19 -> 11.977563 | T19: =S19-K19 -> 0.038794148
B20: 75 | C20: 5 | D20: ='Defunciones generales'!D37 -> 3338 | E20: =Homicidios!D569 -> 6 | F20: =(D20-E20)/D20 -> 0.99820252 | G20: =LT!G18 -> 54355.74 | H20: =1-LT!E18 -> 0.71080956 | I20: =1-H20 -> 0.28919044 | J20: =LT!F18 -> 2.5 | K20: =LT!K18 -> 9.141638 | L20: =H20^F20 -> 0.71124582 | M20: =1-L20 -> 0.28875418 | N20: =N19*L19 -> 55295.118 | O20: =N20*M20 -> 15966.696 | P20: =(((-5/24)*O19)+((2.5)*O20)+((5/24)*O21))/O20 -> 2.5479729 | Q20: =(C20*N21)+(P20*O20) -> 237324.82 | R20: =R21+Q20 -> 506512.7 | S20: =R20/N20 -> 9.1601705 | T20: =S20-K20 -> 0.018532473
B21: 80 | C21: 5 | D21: ='Defunciones generales'!D38 -> 3111 | E21: =Homicidios!D570 -> 1 | F21: =(D21-E21)/D21 -> 0.99967856 | G21: =LT!G19 -> 38636.58 | H21: =1-LT!E19 -> 0.57860496 | I21: =1-H21 -> 0.42139504 | J21: =LT!F19 -> 2.5 | K21: =LT!K19 -> 6.843766 | L21: =H21^F21 -> 0.57870673 | M21: =1-L21 -> 0.42129327 | N21: =N20*L20 -> 39328.421 | O21: =N21*M21 -> 16568.799 | P21: =C21+(F21*(I21/M21)*(J21-C21)) -> 2.5001999 | Q21: =(C21*N22)+(P21*O21) -> 155223.42 | R21: =R22+Q21 -> 269187.89 | S21: =R21/N21 -> 6.8446146 | T21: =S21-K21 -> 0.00084858968
B22: 85 | C22: 5 | D22: ='Defunciones generales'!D39 -> 4952 | E22: =Homicidios!D571 -> 1 | F22: =(D22-E22)/D22 -> 0.99979806 | G22: =LT!G20 -> 22355.32 | H22: =1-LT!E20 -> 0 | I22: =1-H22 -> 1 | J22: =LT!F20 -> NA | K22: =LT!K20 -> 5.007309 | L22: =H22^F22 -> 0 | M22: =1-L22 -> 1 | N22: =N21*L21 -> 22759.622 | O22: =N22*M22 -> 22759.622 | P22: =K22/F22 -> 5.0083204 | Q22: =(N22/LT!D20) -> 113964.47 | R22: =Q22 -> 113964.47 | S22: =R22/N22 -> 5.0073092 | T22: =S22-K22 -> 2.3689177e-07
B24: Mujeres, 2019
B26: Age x | C26: n | D26: nDx | E26: nDxi | I26: nqx | K26: e0 | M26: nqx_i | O26: ndx_i | Q26: L | R26: T | S26: e0_i | T26: diff | AA26: Hombres | AB26: Mujeres
B27: 0 | C27: 1 | D27: ='Defunciones generales'!D78 -> 485 | E27: =Homicidios!D1218 -> 1 | F27: =(D27-E27)/D27 -> 0.99793814 | G27: =LT!G22 -> 100000 | H27: =1-LT!E22 -> 0.98290413 | I27: =1-H27 -> 0.017095871 | J27: =LT!F22 -> 0.1016151 | K27: =LT!K22 -> 76.572627 | L27: =H27^F27 -> 0.98293908 | M27: =1-L27 -> 0.017060924 | N27: 100000 | O27: =N27*M27 -> 1706.0924 | P27: =C27+(F27*(I27/M27)*(J27-C27)) -> 0.10163102 | Q27: =(C27*N28)+(P27*O27) -> 98467.3 | R27: =R28+Q27 -> 7675536.2 | S27: =R27/N27 -> 76.755362 | T27: =S27-K27 -> 0.18273462 | Z27: Sin homicidios | AA27: =S4 -> 72.193954 | AB27: =S27 -> 76.755362
B28: 1 | C28: 4 | D28: ='Defunciones generales'!D79 -> 106 | E28: =Homicidios!D1219 -> 3 | F28: =(D28-E28)/D28 -> 0.97169811 | G28: =LT!G23 -> 98290.41 | H28: =1-LT!E23 -> 0.99732755 | I28: =1-H28 -> 0.002672449 | J28: =LT!F23 -> 1.4956437 | K28: =LT!K23 -> 76.902704 | L28: =H28^F28 -> 0.99740309 | M28: =1-L28 -> 0.0025969119 | N28: =N27*L27 -> 98293.908 | O28: =N28*M28 -> 255.26062 | P28: =C28+(F28*(I28/M28)*(J28-C28)) -> 1.4957385 | Q28: =(C28*N29)+(P28*O28) -> 392536.39 | R28: =R29+Q28 -> 7577068.9 | S28: =R28/N28 -> 77.085844 | T28: =S28-K28 -> 0.18314038 | V28: Número de años que se espera que viva una mujer de 0 años hasta llegar a los 85 años. | Z28: Con homicidios | AA28: =K4 -> 71.491883 | AB28: =K27 -> 76.572627
B29: 5 | C29: 5 | D29: ='Defunciones generales'!D80 -> 54 | E29: =Homicidios!D1220 -> 1 | F29: =(D29-E29)/D29 -> 0.98148148 | G29: =LT!G24 -> 98027.74 | H29: =1-LT!E24 -> 0.99823928 | I29: =1-H29 -> 0.001760723 | J29: =LT!F24 -> 2.5 | K29: =LT!K24 -> 73.104766 | L29: =H29^F29 -> 0.99827185 | M29: =1-L29 -> 0.0017281452 | N29: =N28*L28 -> 98038.647 | O29: =N29*M29 -> 169.42502 | P29: =C29+(F29*(I29/M29)*(J29-C29)) -> 2.5000408 | Q29: =(C29*N30)+(P29*O29) -> 489769.68 | R29: =R30+Q29 -> 7184532.5 | S29: =R29/N29 -> 73.282656 | T29: =S29-K29 -> 0.17789033 | AA29: =AA27-AA28 -> 0.70207082 | AB29: =AB27-AB28 -> 0.18273462
B30: 10 | C30: 5 | D30: ='Defunciones generales'!D81 -> 76 | E30: =Homicidios!D1221 -> 0 | F30: =(D30-E30)/D30 -> 1 | G30: =LT!G25 -> 97855.14 | H30: =1-LT!E25 -> 0.99842062 | I30: =1-H30 -> 0.001579378 | J30: =LT!F25 -> 2.5 | K30: =LT!K25 -> 68.2293 | L30: =H30^F30 -> 0.99842062 | M30: =1-L30 -> 0.001579378 | N30: =N29*L29 -> 97869.222 | O30: =N30*M30 -> 154.5725 | P30: =(((-5/24)*O29)+((2.5)*O30)+((5/24)*O31))/O30 -> 2.6708109 | Q30: =(C30*N31)+(P30*O30) -> 488986.08 | R30: =R31+Q30 -> 6694762.8 | S30: =R30/N30 -> 68.405191 | T30: =S30-K30 -> 0.17589072
B31: 15 | C31: 5 | D31: ='Defunciones generales'!D82 -> 112 | E31: =Homicidios!D1222 -> 3 | F31: =(D31-E31)/D31 -> 0.97321429 | G31: =LT!G26 -> 97700.59 | H31: =1-LT!E26 -> 0.99688587 | I31: =1-H31 -> 0.003114131 | J31: =LT!F26 -> 2.5 | K31: =LT!K26 -> 63.333276 | L31: =H31^F31 -> 0.99696916 | M31: =1-L31 -> 0.0030308433 | N31: =N30*L30 -> 97714.649 | O31: =N31*M31 -> 296.15779 | P31: =(((-5/24)*O30)+((2.5)*O31)+((5/24)*O32))/O31 -> 2.6283104 | Q31: =(C31*N32)+(P31*O31) -> 487870.85 | R31: =R32+Q31 -> 6205776.7 | S31: =R31/N31 -> 63.509174 | T31: =S31-K31 -> 0.17589839 | V31: Sin COVID | W31: Con COVID
B32: 20 | C32: 5 | D32: ='Defunciones generales'!D83 -> 200 | E32: =Homicidios!D1223 -> 19 | F32: =(D32-E32)/D32 -> 0.905 | G32: =LT!G27 -> 97396.33 | H32: =1-LT!E27 -> 0.99617857 | I32: =1-H32 -> 0.003821433 | J32: =LT!F27 -> 2.5 | K32: =LT!K27 -> 58.523311 | L32: =H32^F32 -> 0.99654097 | M32: =1-L32 -> 0.0034590255 | N32: =N31*L31 -> 97418.492 | O32: =N32*M32 -> 336.97305 | P32: =(((-5/24)*O31)+((2.5)*O32)+((5/24)*O33))/O32 -> 2.5637166 | Q32: =(C32*N33)+(P32*O32) -> 486271.5 | R32: =R33+Q32 -> 5717905.9 | S32: =R32/N32 -> 58.694256 | T32: =S32-K32 -> 0.1709447 | V32: =([1]TV!M29-[1]TV!M47)/[1]TV!J29 -> 73.3257 | W32: =(R27-R45)/N27 -> 74.598251
B33: 25 | C33: 5 | D33: ='Defunciones generales'!D84 -> 247 | E33: =Homicidios!D1224 -> 25 | F33: =(D33-E33)/D33 -> 0.89878543 | G33: =LT!G28 -> 97024.14 | H33: =1-LT!E28 -> 0.99542579 | I33: =1-H33 -> 0.004574213 | J33: =LT!F28 -> 2.5 | K33: =LT!K28 -> 53.738221 | L33: =H33^F33 -> 0.99588781 | M33: =1-L33 -> 0.0041121893 | N33: =N32*L32 -> 97081.519 | O33: =N33*M33 -> 399.21758 | P33: =(((-5/24)*O32)+((2.5)*O33)+((5/24)*O34))/O33 -> 2.5999699 | Q33: =(C33*N34)+(P33*O33) -> 484449.46 | R33: =R34+Q33 -> 5231634.4 | S33: =R33/N33 -> 53.889087 | T33: =S33-K33 -> 0.15086559 | V33: Diff | W33: =W32-V32 -> 1.2725514
B34: 30 | C34: 5 | D34: ='Defunciones generales'!D85 -> 259 | E34: =Homicidios!D1225 -> 20 | F34: =(D34-E34)/D34 -> 0.92277992 | G34: =LT!G29 -> 96580.33 | H34: =1-LT!E29 -> 0.99407712 | I34: =1-H34 -> 0.005922881 | J34: =LT!F29 -> 2.5 | K34: =LT!K29 -> 48.973673 | L34: =H34^F34 -> 0.99453323 | M34: =1-L34 -> 0.0054667682 | N34: =N33*L33 -> 96682.301 | O34: =N34*M34 -> 528.53973 | P34: =(((-5/24)*O33)+((2.5)*O34)+((5/24)*O35))/O34 -> 2.6274092 | Q34: =(C34*N35)+(P34*O34) -> 482157.5 | R34: =R35+Q34 -> 4747184.9 | S34: =R34/N34 -> 49.100868 | T34: =S34-K34 -> 0.12719503
B35: 35 | C35: 5 | D35: ='Defunciones generales'!D86 -> 352 | E35: =Homicidios!D1226 -> 14 | F35: =(D35-E35)/D35 -> 0.96022727 | G35: =LT!G30 -> 96008.3 | H35: =1-LT!E30 -> 0.99217648 | I35: =1-H35 -> 0.007823515 | J35: =LT!F30 -> 2.5 | K35: =LT!K30 -> 44.250571 | L35: =H35^F35 -> 0.99248648 | M35: =1-L35 -> 0.0075135244 | N35: =N34*L34 -> 96153.761 | O35: =N35*M35 -> 722.45363 | P35: =(((-5/24)*O34)+((2.5)*O35)+((5/24)*O36))/O35 -> 2.6512977 | Q35: =(C35*N36)+(P35*O35) -> 479071.98 | R35: =R36+Q35 -> 4265027.4 | S35: =R35/N35 -> 44.356324 | T35: =S35-K35 -> 0.10575318
B36: 40 | C36: 5 | D36: ='Defunciones generales'!D87 -> 601 | E36: =Homicidios!D1227 -> 10 | F36: =(D36-E36)/D36 -> 0.98336106 | G36: =LT!G31 -> 95257.18 | H36: =1-LT!E31 -> 0.98877804 | I36: =1-H36 -> 0.011221964 | J36: =LT!F31 -> 2.5 | K36: =LT!K31 -> 39.579783 | L36: =H36^F36 -> 0.98896372 | M36: =1-L36 -> 0.011036277 | N36: =N35*L35 -> 95431.308 | O36: =N36*M36 -> 1053.2063 | P36: =(((-5/24)*O35)+((2.5)*O36)+((5/24)*O37))/O36 -> 2.6437112 | Q36: =(C36*N37)+(P36*O36) -> 474674.88 | R36: =R37+Q36 -> 3785955.4 | S36: =R36/N36 -> 39.672048 | T36: =S36-K36 -> 0.092265114
B37: 45 | C37: 5 | D37: ='Defunciones generales'!D88 -> 915 | E37: =Homicidios!D1228 -> 14 | F37: =(D37-E37)/D37 -> 0.98469945 | G37: =LT!G32 -> 94188.2 | H37: =1-LT!E32 -> 0.98441049 | I37: =1-H37 -> 0.015589506 | J37: =LT!F32 -> 2.5 | K37: =LT!K32 -> 35.000613 | L37: =H37^F37 -> 0.98464718 | M37: =1-L37 -> 0.015352819 | N37: =N36*L36 -> 94378.101 | O37: =N37*M37 -> 1448.9699 | P37: =(((-5/24)*O36)+((2.5)*O37)+((5/24)*O38))/O37 -> 2.644259 | Q37: =(C37*N38)+(P37*O37) -> 468477.11 | R37: =R38+Q37 -> 3311280.5 | S37: =R37/N37 -> 35.085263 | T37: =S37-K37 -> 0.084650444
B38: 50 | C38: 5 | D38: ='Defunciones generales'!D89 -> 1294 | E38: =Homicidios!D1229 -> 7 | F38: =(D38-E38)/D38 -> 0.99459042 | G38: =LT!G33 -> 92719.86 | H38: =1-LT!E33 -> 0.97775084 | I38: =1-H38 -> 0.022249164 | J38: =LT!F33 -> 2.5 | K38: =LT!K33 -> 30.515306 | L38: =H38^F38 -> 0.97786985 | M38: =1-L38 -> 0.022130147 | N38: =N37*L37 -> 92929.131 | O38: =N38*M38 -> 2056.5353 | P38: =(((-5/24)*O37)+((2.5)*O38)+((5/24)*O39))/O38 -> 2.6332256 | Q38: =(C38*N39)+(P38*O38) -> 459778.3 | R38: =R39+Q38 -> 2842803.4 | S38: =R38/N38 -> 30.59109 | T38: =S38-K38 -> 0.075784167
B39: 55 | C39: 5 | D39: ='Defunciones generales'!D90 -> 1715 | E39: =Homicidios!D1230 -> 4 | F39: =(D39-E39)/D39 -> 0.99766764 | G39: =LT!G34 -> 90656.92 | H39: =1-LT!E34 -> 0.96951279 | I39: =1-H39 -> 0.030487207 | J39: =LT!F34 -> 2.5 | K39: =LT!K34 -> 26.152806 | L39: =H39^F39 -> 0.96958281 | M39: =1-L39 -> 0.030417192 | N39: =N38*L38 -> 90872.596 | O39: =N39*M39 -> 2764.0892 | P39: =(((-5/24)*O38)+((2.5)*O39)+((5/24)*O40))/O39 -> 2.6652162 | Q39: =(C39*N40)+(P39*O39) -> 447909.43 | R39: =R40+Q39 -> 2383025.1 | S39: =R39/N39 -> 26.223804 | T39: =S39-K39 -> 0.070997867
B40: 60 | C40: 5 | D40: ='Defunciones generales'!D91 -> 2222 | E40: =Homicidios!D1231 -> 5 | F40: =(D40-E40)/D40 -> 0.99774977 | G40: =LT!G35 -> 87893.04 | H40: =1-LT!E35 -> 0.95167426 | I40: =1-H40 -> 0.048325737 | J40: =LT!F35 -> 2.5 | K40: =LT!K35 -> 21.89659 | L40: =H40^F40 -> 0.95178034 | M40: =1-L40 -> 0.048219658 | N40: =N39*L39 -> 88108.507 | O40: =N40*M40 -> 4248.5621 | P40: =(((-5/24)*O39)+((2.5)*O40)+((5/24)*O41))/O40 -> 2.6750345 | Q40: =(C40*N41)+(P40*O40) -> 430664.77 | R40: =R41+Q40 -> 1935115.7 | S40: =R40/N40 -> 21.96287 | T40: =S40-K40 -> 0.066280288
B41: 65 | C41: 5 | D41: ='Defunciones generales'!D92 -> 2715 | E41: =Homicidios!D1232 -> 3 | F41: =(D41-E41)/D41 -> 0.99889503 | G41: =LT!G36 -> 83645.54 | H41: =1-LT!E36 -> 0.92439395 | I41: =1-H41 -> 0.075606045 | J41: =LT!F36 -> 2.5 | K41: =LT!K36 -> 17.881544 | L41: =H41^F41 -> 0.92447426 | M41: =1-L41 -> 0.07552574 | N41: =N40*L40 -> 83859.945 | O41: =N41*M41 -> 6333.5844 | P41: =(((-5/24)*O40)+((2.5)*O41)+((5/24)*O42))/O41 -> 2.6974043 | Q41: =(C41*N42)+(P41*O41) -> 404716.04 | R41: =R42+Q41 -> 1504450.9 | S41: =R41/N41 -> 17.940042 | T41: =S41-K41 -> 0.058498026
B42: 70 | C42: 5 | D42: ='Defunciones generales'!D93 -> 3068 | E42: =Homicidios!D1233 -> 2 | F42: =(D42-E42)/D42 -> 0.99934811 | G42: =LT!G37 -> 77321.44 | H42: =1-LT!E37 -> 0.86770805 | I42: =1-H42 -> 0.13229195 | J42: =LT!F37 -> 2.5 | K42: =LT!K37 -> 14.139598 | L42: =H42^F42 -> 0.86778832 | M42: =1-L42 -> 0.13221168 | N42: =N41*L41 -> 77526.36 | O42: =N42*M42 -> 10249.89 | P42: =(((-5/24)*O41)+((2.5)*O42)+((5/24)*O43))/O42 -> 2.6659245 | Q42: =(C42*N43)+(P42*O42) -> 363707.78 | R42: =R43+Q42 -> 1099734.9 | S42: =R42/N42 -> 14.185303 | T42: =S42-K42 -> 0.045704757
B43: 75 | C43: 5 | D43: ='Defunciones generales'!D94 -> 3311 | E43: =Homicidios!D1234 -> 1 | F43: =(D43-E43)/D43 -> 0.99969798 | G43: =LT!G38 -> 67092.43 | H43: =1-LT!E38 -> 0.78445878 | I43: =1-H43 -> 0.21554122 | J43: =LT!F38 -> 2.5 | K43: =LT!K38 -> 10.914187 | L43: =H43^F43 -> 0.7845163 | M43: =1-L43 -> 0.2154837 | N43: =N42*L42 -> 67276.47 | O43: =N43*M43 -> 14496.983 | P43: =(((-5/24)*O42)+((2.5)*O43)+((5/24)*O44))/O43 -> 2.613511 | Q43: =(C43*N44)+(P43*O43) -> 301785.46 | R43: =R44+Q43 -> 736027.11 | S43: =R43/N43 -> 10.940335 | T43: =S43-K43 -> 0.02614781
...

Sheet LT
A1: year | B1: sex | C1: age | D1: mx | E1: qx | F1: ax | G1: lx | H1: dx | I1: Lx | J1: Tx | K1: ex
A2: 2019 | B2: h | C2: 0 | D2: 0.020924761 | E2: 0.020538474 | F2: 0.1011621 | G2: 100000 | H2: 2053.8474 | I2: 98153.92 | J2: 7149188.3 | K2: 71.491883
A3: 2019 | B3: h | C3: 1 | D3: 0.000848757 | E3: 0.003388104 | F3: 1.5920759 | G3: 97946.15 | H3: 331.8517 | I3: 390985.54 | J3: 7051034.3 | K3: 71.988885
A4: 2019 | B4: h | C4: 5 | D4: 0.0004447683 | E4: 0.002221371 | F4: 2.5 | G4: 97614.3 | H4: 216.8376 | I4: 487529.41 | J4: 6660048.8 | K4: 68.228208
A5: 2019 | B5: h | C5: 10 | D5: 0.0004131315 | E5: 0.002063526 | F5: 2.5 | G5: 97397.46 | H5: 200.9822 | I5: 486484.86 | J5: 6172519.4 | K5: 63.37454
A6: 2019 | B6: h | C6: 15 | D6: 0.0013374979 | E6: 0.006665203 | F6: 2.5 | G6: 97196.48 | H6: 647.8343 | I6: 484362.82 | J6: 5686034.5 | K6: 58.500416
A7: 2019 | B7: h | C7: 20 | D7: 0.0017646664 | E7: 0.008784577 | F7: 2.5 | G7: 96548.65 | H7: 848.1391 | I7: 480622.89 | J7: 5201671.7 | K7: 53.876174
A8: 2019 | B8: h | C8: 25 | D8: 0.0019440412 | E8: 0.009673193 | F8: 2.5 | G8: 95700.51 | H8: 925.7295 | I8: 476188.21 | J8: 4721048.8 | K8: 49.331492
A9: 2019 | B9: h | C9: 30 | D9: 0.0023053343 | E9: 0.01146062 | F9: 2.5 | G9: 94774.78 | H9: 1086.1777 | I9: 471158.45 | J9: 4244860.6 | K9: 44.788927
A10: 2019 | B10: h | C10: 35 | D10: 0.002892646 | E10: 0.014359389 | F10: 2.5 | G10: 93688.6 | H10: 1345.311 | I10: 465079.72 | J10: 3773702.2 | K10: 40.279203
A11: 2019 | B11: h | C11: 40 | D11: 0.0037950273 | E11: 0.018796801 | F11: 2.5 | G11: 92343.29 | H11: 1735.7584 | I11: 457377.05 | J11: 3308622.4 | K11: 35.829593
A12: 2019 | B12: h | C12: 45 | D12: 0.004822526 | E12: 0.023825383 | F12: 2.5 | G12: 90607.53 | H12: 2158.7592 | I12: 447640.76 | J12: 2851245.4 | K12: 31.468084
A13: 2019 | B13: h | C13: 50 | D13: 0.0066950896 | E13: 0.032924369 | F13: 2.5 | G13: 88448.77 | H13: 2912.12 | I13: 434963.56 | J13: 2403604.6 | K13: 27.175105
... A19: 2019 | B19: h | C19: 80 | D19: 0.10677657 | E19: 0.42139504 | F19: 2.5 | G19: 38636.58 | H19: 16281.264 | I19: 152479.75 | J19: 264419.7 | K19: 6.843766
A20: 2019 | B20: h | C20: 85 | D20: 0.19970806 | E20: 1 | F20: NA | G20: 22355.32 | H20: 22355.319 | I20: 111939.99 | J20: 111940 | K20: 5.007309
A21: year | B21: sex | C21: age | D21: mx | E21: qx | F21: ax | G21: lx | H21: dx | I21: Lx | J21: Tx | K21: ex
A22: 2019 | B22: m | C22: 0 | D22: 0.017362537 | E22: 0.017095871 | F22: 0.1016151 | G22: 100000 | H22: 1709.5871 | I22: 98464.13 | J22: 7657262.7 | K22: 76.572627
A23: 2019 | B23: m | C23: 1 | D23: 0.0006692321 | E23: 0.002672449 | F23: 1.4956437 | G23: 98290.41 | H23: 262.6761 | I23: 392503.82 | J23: 7558798.6 | K23: 76.902704
A24: 2019 | B24: m | C24: 5 | D24: 0.0003524549 | E24: 0.001760723 | F24: 2.5 | G24: 98027.74 | H24: 172.5997 | I24: 489707.18 | J24: 7166294.7 | K24: 73.104766
A25: 2019 | B25: m | C25: 10 | D25: 0.0003161252 | E25: 0.001579378 | F25: 2.5 | G25: 97855.14 | H25: 154.5503 | I25: 488889.31 | J25: 6676587.5 | K25: 68.2293
A26: 2019 | B26: m | C26: 15 | D26: 0.0006237975 | E26: 0.003114131 | F26: 2.5 | G26: 97700.59 | H26: 304.2524 | I26: 487742.3 | J26: 6187698.2 | K26: 63.333276
A27: 2019 | B27: m | C27: 20 | D27: 0.0007657497 | E27: 0.003821433 | F27: 2.5 | G27: 97396.33 | H27: 372.1935 | I27: 486051.19 | J27: 5699955.9 | K27: 58.523311
A28: 2019 | B28: m | C28: 25 | D28: 0.0009169397 | E28: 0.004574213 | F28: 2.5 | G28: 97024.14 | H28: 443.809 | I28: 484011.18 | J28: 5213904.7 | K28: 53.738221
A29: 2019 | B29: m | C29: 30 | D29: 0.0011880946 | E29: 0.005922881 | F29: 2.5 | G29: 96580.33 | H29: 572.0338 | I29: 481471.57 | J29: 4729893.6 | K29: 48.973673
A30: 2019 | B30: m | C30: 35 | D30: 0.0015708478 | E30: 0.007823515 | F30: 2.5 | G30: 96008.3 | H30: 751.1224 | I30: 478163.68 | J30: 4248422 | K30: 44.250571
A31: 2019 | B31: m | C31: 40 | D31: 0.0022570571 | E31: 0.011221964 | F31: 2.5 | G31: 95257.18 | H31: 1068.9726 | I31: 473613.45 | J31: 3770258.3 | K31: 39.579783
A32: 2019 | B32: m | C32: 45 | D32: 0.0031423954 | E32: 0.015589506 | F32: 2.5 | G32: 94188.2 | H32: 1468.3476 | I32: 467270.15 | J32: 3296644.9 | K32: 35.000613
A33: 2019 | B33: m | C33: 50 | D33: 0.0044998922 | E33: 0.022249164 | F33: 2.5 | G33: 92719.86 | H33: 2062.9392 | I33: 458441.93 | J33: 2829374.7 | K33: 30.515306
... A39: 2019 | B39: m | C39: 80 | D39: 0.083092834 | E39: 0.34400359 | F39: 2.5 | G39: 52631.25 | H39: 18105.338 | I39: 217892.89 | J39: 432950.1 | K39: 8.226104
A40: 2019 | B40: m | C40: 85 | D40: 0.1605429 | E40: 1 | F40: NA | G40: 34525.91 | H40: 34525.91 | I40: 215057.23 | J40: 215057.2 | K40: 6.228865

Sheet Homicidios
A1: year | B1: sex | C1: age | D1: deaths
A553: 2019 | B553: male | C553: 0 | D553: 0
A554: 2019 | B554: male | C554: 1 | D554: 3
A555: 2019 | B555: male | C555: 5 | D555: 0
A556: 2019 | B556: male | C556: 10 | D556: 6
A557: 2019 | B557: male | C557: 15 | D557: 54
A558: 2019 | B558: male | C558: 20 | D558: 168
A559: 2019 | B559: male | C559: 25 | D559: 190
A560: 2019 | B560: male | C560: 30 | D560: 173
A561: 2019 | B561: male | C561: 35 | D561: 142
A562: 2019 | B562: male | C562: 40 | D562: 110
A563: 2019 | B563: male | C563: 45 | D563: 100
A564: 2019 | B564: male | C564: 50 | D564: 52
... A1236: 2019 | B1236: female | C1236: 85 | D1236: 1

Sheet Defunciones generales
A1: year | B1: sex | C1: age | D1: deaths
A21: 2019 | B21: male | C21: 0 | D21: 694
A22: 2019 | B22: male | C22: 1 | D22: 107
A23: 2019 | B23: male | C23: 5 | D23: 56
A24: 2019 | B24: male | C24: 10 | D24: 88
A25: 2019 | B25: male | C25: 15 | D25: 290
A26: 2019 | B26: male | C26: 20 | D26: 561
A27: 2019 | B27: male | C27: 25 | D27: 745
A28: 2019 | B28: male | C28: 30 | D28: 866
A29: 2019 | B29: male | C29: 35 | D29: 962
A30: 2019 | B30: male | C30: 40 | D30: 1209
A31: 2019 | B31: male | C31: 45 | D31: 1680
A32: 2019 | B32: male | C32: 50 | D32: 2027
... A96: 2019 | B96: female | C96: 85 | D96: 8650
