Workbook

Sheet 2010
A1: Población total
A2: Entidad y municipio : Distrito Federal
A4: Consulta de: Población total con estimación Por: Edad Según: Sexo
F5: Prorrateo
B6: Total | C6: Hombre | D6: Mujer | F6: Total | G6: Hombre | H6: Mujer
A7: Total | B7: 8851080 | C7: 4233783 | D7: 4617297 | F7: =SUM(F8:F26) -> 8851080 | G7: =SUM(G8:G26) -> 4233783 | H7: =SUM(H8:H26) -> 4617297
A8: Menos de un año | B8: =C8+D8 -> 112784 | C8: 57597 | D8: 55187 | F8: =B8+(B8/SUM(B$8:B$26)*B$27) -> 115365.07 | G8: =C8+(C8/SUM(C$8:C$26)*C$27) -> 58974.56 | H8: =D8+(D8/SUM(D$8:D$26)*D$27) -> 56397.833
A9: De 1 a 4 años | B9: =C9+D9 -> 505461 | C9: 257104 | D9: 248357 | F9: =B9+(B9/SUM(B$8:B$26)*B$27) -> 517028.53 | G9: =C9+(C9/SUM(C$8:C$26)*C$27) -> 263253.21 | H9: =D9+(D9/SUM(D$8:D$26)*D$27) -> 253806.09
A10: De 5 a 9 años | B10: 658948 | C10: 334885 | D10: 324063 | F10: =B10+(B10/SUM(B$8:B$26)*B$27) -> 674028.09 | G10: =C10+(C10/SUM(C$8:C$26)*C$27) -> 342894.52 | H10: =D10+(D10/SUM(D$8:D$26)*D$27) -> 331173.12
A11: De 10 a 14 años | B11: 660345 | C11: 334674 | D11: 325671 | F11: =B11+(B11/SUM(B$8:B$26)*B$27) -> 675457.06 | G11: =C11+(C11/SUM(C$8:C$26)*C$27) -> 342678.47 | H11: =D11+(D11/SUM(D$8:D$26)*D$27) -> 332816.4
A12: De 15 a 19 años | B12: 723372 | C12: 363265 | D12: 360107 | F12: =B12+(B12/SUM(B$8:B$26)*B$27) -> 739926.44 | G12: =C12+(C12/SUM(C$8:C$26)*C$27) -> 371953.29 | H12: =D12+(D12/SUM(D$8:D$26)*D$27) -> 368007.94
A13: De 20 a 24 años | B13: 753404 | C13: 372368 | D13: 381036 | F13: =B13+(B13/SUM(B$8:B$26)*B$27) -> 770645.73 | G13: =C13+(C13/SUM(C$8:C$26)*C$27) -> 381274.01 | H13: =D13+(D13/SUM(D$8:D$26)*D$27) -> 389396.14
A14: De 25 a 29 años | B14: 726696 | C14: 352969 | D14: 373727 | F14: =B14+(B14/SUM(B$8:B$26)*B$27) -> 743326.51 | G14: =C14+(C14/SUM(C$8:C$26)*C$27) -> 361411.04 | H14: =D14+(D14/SUM(D$8:D$26)*D$27) -> 381926.77
A15: De 30 a 34 años | B15: 702642 | C15: 335988 | D15: 366654 | F15: =B15+(B15/SUM(B$8:B$26)*B$27) -> 718722.03 | G15: =C15+(C15/SUM(C$8:C$26)*C$27) -> 344023.9 | H15: =D15+(D15/SUM(D$8:D$26)*D$27) -> 374698.59
A16: De 35 a 39 años | B16: 722214 | C16: 341865 | D16: 380349 | F16: =B16+(B16/SUM(B$8:B$26)*B$27) -> 738741.94 | G16: =C16+(C16/SUM(C$8:C$26)*C$27) -> 350041.46 | H16: =D16+(D16/SUM(D$8:D$26)*D$27) -> 388694.06
A17: De 40 a 44 años | B17: 629563 | C17: 295151 | D17: 334412 | F17: =B17+(B17/SUM(B$8:B$26)*B$27) -> 643970.61 | G17: =C17+(C17/SUM(C$8:C$26)*C$27) -> 302210.19 | H17: =D17+(D17/SUM(D$8:D$26)*D$27) -> 341749.18
A18: De 45 a 49 años | B18: 555481 | C18: 256078 | D18: 299403 | F18: =B18+(B18/SUM(B$8:B$26)*B$27) -> 568193.24 | G18: =C18+(C18/SUM(C$8:C$26)*C$27) -> 262202.67 | H18: =D18+(D18/SUM(D$8:D$26)*D$27) -> 305972.06
A19: De 50 a 54 años | B19: 506310 | C19: 230325 | D19: 275985 | F19: =B19+(B19/SUM(B$8:B$26)*B$27) -> 517896.95 | G19: =C19+(C19/SUM(C$8:C$26)*C$27) -> 235833.73 | H19: =D19+(D19/SUM(D$8:D$26)*D$27) -> 282040.26
A20: De 55 a 59 años | B20: 392186 | C20: 179065 | D20: 213121 | F20: =B20+(B20/SUM(B$8:B$26)*B$27) -> 401161.22 | G20: =C20+(C20/SUM(C$8:C$26)*C$27) -> 183347.74 | H20: =D20+(D20/SUM(D$8:D$26)*D$27) -> 217796.99
A21: De 60 a 64 años | B21: 315793 | C21: 141010 | D21: 174783 | F21: =B21+(B21/SUM(B$8:B$26)*B$27) -> 323019.95 | G21: =C21+(C21/SUM(C$8:C$26)*C$27) -> 144382.57 | H21: =D21+(D21/SUM(D$8:D$26)*D$27) -> 178617.83
... A26: 85 y más años | B26: 71281 | C26: 24600 | D26: 46681 | F26: =B26+(B26/SUM(B$8:B$26)*B$27) -> 72912.273 | G26: =C26+(C26/SUM(C$8:C$26)*C$27) -> 25188.363 | H26: =D26+(D26/SUM(D$8:D$26)*D$27) -> 47705.206
A27: No especificado | B27: 198026 | C27: 98895 | D27: 99131
A30: FUENTE: INEGI. Censo de Población y Vivienda 2010.

Sheet 2020
A1: Población total
A2: Entidad y municipio : Ciudad de México
A4: Consulta de: Población total Por: Edad Según: Sexo
F5: Prorrateo
B6: Total | C6: Hombres | D6: Mujeres | F6: Total | G6: Hombres | H6: Mujeres
A7: Total | B7: 9209944 | C7: 4404927 | D7: 4805017 | F7: =SUM(F8:F26) -> 9209944 | G7: =SUM(G8:G26) -> 4404927 | H7: =SUM(H8:H26) -> 4805017
A8: Menos de 1 año | B8: =C8+D8 -> 81536 | C8: 41310 | D8: 40226 | F8: =B8+(B8/SUM(B$8:B$26)*B$27) -> 81621.309 | G8: =C8+(C8/SUM(C$8:C$26)*C$27) -> 41354.904 | H8: =D8+(D8/SUM(D$8:D$26)*D$27) -> 40266.585
A9: De 1 a 4 años | B9: =C9+D9 -> 398368 | C9: 201567 | D9: 196801 | F9: =B9+(B9/SUM(B$8:B$26)*B$27) -> 398784.8 | G9: =C9+(C9/SUM(C$8:C$26)*C$27) -> 201786.11 | H9: =D9+(D9/SUM(D$8:D$26)*D$27) -> 196999.56
A10: De 5 a 9 años | B10: 563907 | C10: 286280 | D10: 277627 | F10: =B10+(B10/SUM(B$8:B$26)*B$27) -> 564497 | G10: =C10+(C10/SUM(C$8:C$26)*C$27) -> 286591.19 | H10: =D10+(D10/SUM(D$8:D$26)*D$27) -> 277907.1
A11: De 10 a 14 años | B11: 608962 | C11: 309140 | D11: 299822 | F11: =B11+(B11/SUM(B$8:B$26)*B$27) -> 609599.14 | G11: =C11+(C11/SUM(C$8:C$26)*C$27) -> 309476.04 | H11: =D11+(D11/SUM(D$8:D$26)*D$27) -> 300124.5
A12: De 15 a 19 años | B12: 650389 | C12: 331109 | D12: 319280 | F12: =B12+(B12/SUM(B$8:B$26)*B$27) -> 651069.48 | G12: =C12+(C12/SUM(C$8:C$26)*C$27) -> 331468.92 | H12: =D12+(D12/SUM(D$8:D$26)*D$27) -> 319602.13
A13: De 20 a 24 años | B13: 714605 | C13: 359049 | D13: 355556 | F13: =B13+(B13/SUM(B$8:B$26)*B$27) -> 715352.67 | G13: =C13+(C13/SUM(C$8:C$26)*C$27) -> 359439.29 | H13: =D13+(D13/SUM(D$8:D$26)*D$27) -> 355914.73
A14: De 25 a 29 años | B14: 752289 | C14: 372081 | D14: 380208 | F14: =B14+(B14/SUM(B$8:B$26)*B$27) -> 753076.1 | G14: =C14+(C14/SUM(C$8:C$26)*C$27) -> 372485.46 | H14: =D14+(D14/SUM(D$8:D$26)*D$27) -> 380591.6
A15: De 30 a 34 años | B15: 743611 | C15: 363448 | D15: 380163 | F15: =B15+(B15/SUM(B$8:B$26)*B$27) -> 744389.02 | G15: =C15+(C15/SUM(C$8:C$26)*C$27) -> 363843.07 | H15: =D15+(D15/SUM(D$8:D$26)*D$27) -> 380546.55
A16: De 35 a 39 años | B16: 705850 | C16: 340545 | D16: 365305 | F16: =B16+(B16/SUM(B$8:B$26)*B$27) -> 706588.51 | G16: =C16+(C16/SUM(C$8:C$26)*C$27) -> 340915.18 | H16: =D16+(D16/SUM(D$8:D$26)*D$27) -> 365673.56
A17: De 40 a 44 años | B17: 670307 | C17: 317312 | D17: 352995 | F17: =B17+(B17/SUM(B$8:B$26)*B$27) -> 671008.32 | G17: =C17+(C17/SUM(C$8:C$26)*C$27) -> 317656.92 | H17: =D17+(D17/SUM(D$8:D$26)*D$27) -> 353351.14
A18: De 45 a 49 años | B18: 668945 | C18: 313846 | D18: 355099 | F18: =B18+(B18/SUM(B$8:B$26)*B$27) -> 669644.9 | G18: =C18+(C18/SUM(C$8:C$26)*C$27) -> 314187.15 | H18: =D18+(D18/SUM(D$8:D$26)*D$27) -> 355457.27
A19: De 50 a 54 años | B19: 623483 | C19: 286394 | D19: 337089 | F19: =B19+(B19/SUM(B$8:B$26)*B$27) -> 624135.33 | G19: =C19+(C19/SUM(C$8:C$26)*C$27) -> 286705.31 | H19: =D19+(D19/SUM(D$8:D$26)*D$27) -> 337429.1
A20: De 55 a 59 años | B20: 526447 | C20: 239651 | D20: 286796 | F20: =B20+(B20/SUM(B$8:B$26)*B$27) -> 526997.8 | G20: =C20+(C20/SUM(C$8:C$26)*C$27) -> 239911.5 | H20: =D20+(D20/SUM(D$8:D$26)*D$27) -> 287085.35
A21: De 60 a 64 años | B21: 469514 | C21: 209065 | D21: 260449 | F21: =B21+(B21/SUM(B$8:B$26)*B$27) -> 470005.24 | G21: =C21+(C21/SUM(C$8:C$26)*C$27) -> 209292.26 | H21: =D21+(D21/SUM(D$8:D$26)*D$27) -> 260711.77
... A26: 85 años y más | B26: 105470 | C26: 36668 | D26: 68802 | F26: =B26+(B26/SUM(B$8:B$26)*B$27) -> 105580.35 | G26: =C26+(C26/SUM(C$8:C$26)*C$27) -> 36707.858 | H26: =D26+(D26/SUM(D$8:D$26)*D$27) -> 68871.416
A27: No especificado | B27: 9626 | C27: 4783 | D27: 4843
A30: FUENTE: INEGI. Censo de Población y Vivienda 2020. Cuestionario Básico.

Sheet 2010 y 2020
G1: Censo 2010 | H1: 40341 | I1: =2010 + (6-1) / 12 + 12/365 -> 2010.4495
G2: Censo 2020 | H2: 43905 | I2: =2020 + (3-1) / 12 + 15/365 -> 2020.2078 | K2: Delta | L2: =I2- I1 -> 9.7582192
B3: 2010 | D3: 2020 | H3: 2019.5
B4: Hombre | C4: Mujer | D4: Hombre | E4: Mujer | G4: r | H4: Hombre | I4: Mujer | K4: APV | L4: Hombre | M4: Mujer
A5: Menos de un año | B5: 57597 | C5: 55187 | D5: 41310 | E5: 40226 | H5: =LN(D5/B5)/$L$2 -> -0.034060096 | I5: =LN(E5/C5)/$L$2 -> -0.032404874 | L5: =B5 * EXP(H5* ( $H$3- $I$1) ) -> 42317.938 | M5: =C5 * EXP(I5* ( $H$3- $I$1) ) -> 41159.243
A6: De 1 a 4 años | B6: 257104 | C6: 248357 | D6: 201567 | E6: 196801 | H6: =LN(D6/B6)/$L$2 -> -0.024938858 | I6: =LN(E6/C6)/$L$2 -> -0.023843916 | L6: =B6 * EXP(H6* ( $H$3- $I$1) ) -> 205156.4 | M6: =C6 * EXP(I6* ( $H$3- $I$1) ) -> 200150.36
A7: De 5 a 9 años | B7: ='2010'!G10 -> 342894.52 | C7: ='2010'!H10 -> 331173.12 | D7: ='2020'!G10 -> 286591.19 | E7: ='2020'!H10 -> 277907.1 | H7: =LN(D7/B7)/$L$2 -> -0.018381027 | I7: =LN(E7/C7)/$L$2 -> -0.017969913 | L7: =B7 * EXP(H7* ( $H$3- $I$1) ) -> 290343.93 | M7: =C7 * EXP(I7* ( $H$3- $I$1) ) -> 281464.22
A8: De 10 a 14 años | B8: ='2010'!G11 -> 342678.47 | C8: ='2010'!H11 -> 332816.4 | D8: ='2020'!G11 -> 309476.04 | E8: ='2020'!H11 -> 300124.5 | H8: =LN(D8/B8)/$L$2 -> -0.010443702 | I8: =LN(E8/C8)/$L$2 -> -0.01059554 | L8: =B8 * EXP(H8* ( $H$3- $I$1) ) -> 311772.06 | M8: =C8 * EXP(I8* ( $H$3- $I$1) ) -> 302383.63
A9: De 15 a 19 años | B9: ='2010'!G12 -> 371953.29 | C9: ='2010'!H12 -> 368007.94 | D9: ='2020'!G12 -> 331468.92 | E9: ='2020'!H12 -> 319602.13 | H9: =LN(D9/B9)/$L$2 -> -0.01180894 | I9: =LN(E9/C9)/$L$2 -> -0.014452191 | L9: =B9 * EXP(H9* ( $H$3- $I$1) ) -> 334250.92 | M9: =C9 * EXP(I9* ( $H$3- $I$1) ) -> 322888.03
A10: De 20 a 24 años | B10: ='2010'!G13 -> 381274.01 | C10: ='2010'!H13 -> 389396.14 | D10: ='2020'!G13 -> 359439.29 | E10: ='2020'!H13 -> 355914.73 | H10: =LN(D10/B10)/$L$2 -> -0.0060434184 | I10: =LN(E10/C10)/$L$2 -> -0.0092133608 | L10: =B10 * EXP(H10* ( $H$3- $I$1) ) -> 360980.01 | M10: =C10 * EXP(I10* ( $H$3- $I$1) ) -> 358243.19
A11: De 25 a 29 años | B11: ='2010'!G14 -> 361411.04 | C11: ='2010'!H14 -> 381926.77 | D11: ='2020'!G14 -> 372485.46 | E11: ='2020'!H14 -> 380591.6 | H11: =LN(D11/B11)/$L$2 -> 0.0030929906 | I11: =LN(E11/C11)/$L$2 -> -0.00035887793 | L11: =B11 * EXP(H11* ( $H$3- $I$1) ) -> 371670.94 | M11: =C11 * EXP(I11* ( $H$3- $I$1) ) -> 380688.28
A12: De 30 a 34 años | B12: ='2010'!G15 -> 344023.9 | C12: ='2010'!H15 -> 374698.59 | D12: ='2020'!G15 -> 363843.07 | E12: ='2020'!H15 -> 380546.55 | H12: =LN(D12/B12)/$L$2 -> 0.0057399336 | I12: =LN(E12/C12)/$L$2 -> 0.0015870301 | L12: =B12 * EXP(H12* ( $H$3- $I$1) ) -> 362367.95 | M12: =C12 * EXP(I12* ( $H$3- $I$1) ) -> 380119.35
A13: De 35 a 39 años | B13: ='2010'!G16 -> 350041.46 | C13: ='2010'!H16 -> 388694.06 | D13: ='2020'!G16 -> 340915.18 | E13: ='2020'!H16 -> 365673.56 | H13: =LN(D13/B13)/$L$2 -> -0.0027072465 | I13: =LN(E13/C13)/$L$2 -> -0.006256421 | L13: =B13 * EXP(H13* ( $H$3- $I$1) ) -> 341569.03 | M13: =C13 * EXP(I13* ( $H$3- $I$1) ) -> 367296.38
A14: De 40 a 44 años | B14: ='2010'!G17 -> 302210.19 | C14: ='2010'!H17 -> 341749.18 | D14: ='2020'!G17 -> 317656.92 | E14: ='2020'!H17 -> 353351.14 | H14: =LN(D14/B14)/$L$2 -> 0.0051084289 | I14: =LN(E14/C14)/$L$2 -> 0.0034212421 | L14: =B14 * EXP(H14* ( $H$3- $I$1) ) -> 316510.49 | M14: =C14 * EXP(I14* ( $H$3- $I$1) ) -> 352496.57
A15: De 45 a 49 años | B15: ='2010'!G18 -> 262202.67 | C15: ='2010'!H18 -> 305972.06 | D15: ='2020'!G18 -> 314187.15 | E15: ='2020'!H18 -> 355457.27 | H15: =LN(D15/B15)/$L$2 -> 0.018535255 | I15: =LN(E15/C15)/$L$2 -> 0.015362561 | L15: =B15 * EXP(H15* ( $H$3- $I$1) ) -> 310092.39 | M15: =C15 * EXP(I15* ( $H$3- $I$1) ) -> 351613.3
A16: De 50 a 54 años | B16: ='2010'!G19 -> 235833.73 | C16: ='2010'!H19 -> 282040.26 | D16: ='2020'!G19 -> 286705.31 | E16: ='2020'!H19 -> 337429.1 | H16: =LN(D16/B16)/$L$2 -> 0.020016754 | I16: =LN(E16/C16)/$L$2 -> 0.018374826 | L16: =B16 * EXP(H16* ( $H$3- $I$1) ) -> 282672.16 | M16: =C16 * EXP(I16* ( $H$3- $I$1) ) -> 333069.24
A17: De 55 a 59 años | B17: ='2010'!G20 -> 183347.74 | C17: ='2010'!H20 -> 217796.99 | D17: ='2020'!G20 -> 239911.5 | E17: ='2020'!H20 -> 287085.35 | H17: =LN(D17/B17)/$L$2 -> 0.027554779 | I17: =LN(E17/C17)/$L$2 -> 0.028306003 | L17: =B17 * EXP(H17* ( $H$3- $I$1) ) -> 235278.02 | M17: =C17 * EXP(I17* ( $H$3- $I$1) ) -> 281391.14
A18: De 60 a 64 años | B18: ='2010'!G21 -> 144382.57 | C18: ='2010'!H21 -> 178617.83 | D18: ='2020'!G21 -> 209292.26 | E18: ='2020'!H21 -> 260711.77 | H18: =LN(D18/B18)/$L$2 -> 0.038046403 | I18: =LN(E18/C18)/$L$2 -> 0.038753686 | L18: =B18 * EXP(H18* ( $H$3- $I$1) ) -> 203731.67 | M18: =C18 * EXP(I18* ( $H$3- $I$1) ) -> 253658.04
... A23: 85 y más años | B23: ='2010'!G26 -> 25188.363 | C23: ='2010'!H26 -> 47705.206 | D23: ='2020'!G26 -> 36707.858 | E23: ='2020'!H26 -> 68871.416 | H23: =LN(D23/B23)/$L$2 -> 0.038594003 | I23: =LN(E23/C23)/$L$2 -> 0.037629887 | L23: =B23 * EXP(H23* ( $H$3- $I$1) ) -> 35718.74 | M23: =C23 * EXP(I23* ( $H$3- $I$1) ) -> 67061.372
B24: =SUM(B6:C23) -> 8724109.3 | D24: =SUM(D6:E23) -> 9127904.8

Sheet Serie de defunciones
A1: Defunciones registradas (mortalidad general)
A2: Ent y mun de residencia : Ciudad de México
AA3: reg | AB3: (Todas)
A4: Consulta de: Defunciones registradas Por: Edad, Año de registro y Año de ocurrencia Según: Sexo | K4: reg | L4: (Todas) | AA4: ocurrencia | AB4: (Varios elementos)
A6: x | B6: age | C6: reg | D6: ocurrencia | E6: Total | F6: Hombre | G6: Mujer | H6: No especificado | K6: Etiquetas de fila | L6: Suma de Hombre | M6: Suma de Mujer | AA6: Etiquetas de fila | AB6: Suma de Hombre | AC6: Suma de Mujer | AE6: APV | AF6: Hombre | AG6: Mujer | AJ6: Defunciones | AK6: Hombre | AL6: Mujer | AN6: nMx | AO6: Hombre | AP6: Mujer
A7: Total | B7: =IF(A7="Menores de 1 año",0,LEFT(A7,2)) -> To | C7: 1990 | D7: Total | E7: 44741 | F7: 23509 | G7: 21203 | H7: 29 | K7: 1990 | L7: 46780 | M7: 42354 | AA7: 0 | AB7: 50449 | AC7: 39014 | AF7: 42317.938 | AG7: 41159.243 | AJ7: 0 | AK7: 50449 | AL7: 39014 | AN7: 0 | AO7: =AK7/AF7 -> 1.1921422 | AP7: =AL7/AG7 -> 0.94787944
A8: Total | B8: =IF(A8="Menores de 1 año",0,LEFT(A8,2)) -> To | C8: 1990 | D8: 1990 | E8: 44584 | F8: 23386 | G8: 21171 | H8: 27 | K8: 1991 | L8: 47674 | M8: 42492 | AA8: 1- | AB8: 6196 | AC8: 5150 | AF8: 205156.4 | AG8: 200150.36 | AJ8: 1- | AK8: 6196 | AL8: 5150 | AN8: 1- | AO8: =AK8/AF8 -> 0.030201349 | AP8: =AL8/AG8 -> 0.025730655
A9: Total | B9: =IF(A9="Menores de 1 año",0,LEFT(A9,2)) -> To | C9: 1990 | D9: No especificado | E9: 157 | F9: 123 | G9: 32 | H9: 2 | K9: 1992 | L9: 48578 | M9: 42252 | AA9: 5- | AB9: 3234 | AC9: 2697 | AF9: 290343.93 | AG9: 281464.22 | AJ9: 5- | AK9: 3234 | AL9: 2697 | AN9: 5- | AO9: =AK9/AF9 -> 0.011138514 | AP9: =AL9/AG9 -> 0.009582035
A10: Total | B10: =IF(A10="Menores de 1 año",0,LEFT(A10,2)) -> To | C10: 1991 | D10: Total | E10: 45203 | F10: 23929 | G10: 21257 | H10: 17 | K10: 1993 | L10: 47746 | M10: 42570 | AA10: 10 | AB10: 3988 | AC10: 2946 | AF10: 311772.05 | AG10: 302383.63 | AJ10: 10 | AK10: 3988 | AL10: 2946 | AN10: 10 | AO10: =AK10/AF10 -> 0.012791397 | AP10: =AL10/AG10 -> 0.0097425909
A11: Total | B11: =IF(A11="Menores de 1 año",0,LEFT(A11,2)) -> To | C11: 1991 | D11: 1989 | E11: 1 | G11: 1 | K11: 1994 | L11: 48398 | M11: 43026 | AA11: 15 | AB11: 12474 | AC11: 5659 | AF11: 334250.92 | AG11: 322888.03 | AJ11: 15 | AK11: 12474 | AL11: 5659 | AN11: 15 | AO11: =AK11/AF11 -> 0.037319269 | AP11: =AL11/AG11 -> 0.0175262
A12: Total | B12: =IF(A12="Menores de 1 año",0,LEFT(A12,2)) -> To | C12: 1991 | D12: 1990 | E12: 1 | G12: 1 | K12: 1995 | L12: 49330 | M12: 43780 | AA12: 20 | AB12: 21116 | AC12: 7332 | AF12: 360980.01 | AG12: 358243.19 | AJ12: 20 | AK12: 21116 | AL12: 7332 | AN12: 20 | AO12: =AK12/AF12 -> 0.058496313 | AP12: =AL12/AG12 -> 0.020466544
A13: Total | B13: =IF(A13="Menores de 1 año",0,LEFT(A13,2)) -> To | C13: 1991 | D13: 1991 | E13: 45068 | F13: 23819 | G13: 21233 | H13: 16 | K13: 1996 | L13: 48454 | M13: 44280 | AA13: 25 | AB13: 25764 | AC13: 8554 | AF13: 371670.94 | AG13: 380688.28 | AJ13: 25 | AK13: 25764 | AL13: 8554 | AN13: 25 | AO13: =AK13/AF13 -> 0.069319383 | AP13: =AL13/AG13 -> 0.022469827
A14: Total | B14: =IF(A14="Menores de 1 año",0,LEFT(A14,2)) -> To | C14: 1991 | D14: No especificado | E14: 133 | F14: 110 | G14: 22 | H14: 1 | K14: 1997 | L14: 48942 | M14: 44842 | AA14: 30 | AB14: 30175 | AC14: 10557 | AF14: 362367.95 | AG14: 380119.35 | AJ14: 30 | AK14: 30175 | AL14: 10557 | AN14: 30 | AO14: =AK14/AF14 -> 0.083271712 | AP14: =AL14/AG14 -> 0.027772856
A15: Total | B15: =IF(A15="Menores de 1 año",0,LEFT(A15,2)) -> To | C15: 1992 | D15: Total | E15: 45328 | F15: 24250 | G15: 21067 | H15: 11 | K15: 1998 | L15: 48498 | M15: 44788 | AA15: 35 | AB15: 35522 | AC15: 14259 | AF15: 341569.03 | AG15: 367296.38 | AJ15: 35 | AK15: 35522 | AL15: 14259 | AN15: 35 | AO15: =AK15/AF15 -> 0.10399655 | AP15: =AL15/AG15 -> 0.03882151
A16: Total | B16: =IF(A16="Menores de 1 año",0,LEFT(A16,2)) -> To | C16: 1992 | D16: 1992 | E16: 45224 | F16: 24169 | G16: 21045 | H16: 10 | K16: 1999 | L16: 48234 | M16: 44964 | AA16: 40 | AB16: 41456 | AC16: 19836 | AF16: 316510.49 | AG16: 352496.57 | AJ16: 40 | AK16: 41456 | AL16: 19836 | AN16: 40 | AO16: =AK16/AF16 -> 0.13097828 | AP16: =AL16/AG16 -> 0.056272889
A17: Total | B17: =IF(A17="Menores de 1 año",0,LEFT(A17,2)) -> To | C17: 1992 | D17: No especificado | E17: 104 | F17: 81 | G17: 22 | H17: 1 | K17: 2000 | L17: 47132 | M17: 44952 | AA17: 45 | AB17: 51386 | AC17: 29202 | AF17: 310092.39 | AG17: 351613.3 | AJ17: 45 | AK17: 51386 | AL17: 29202 | AN17: 45 | AO17: =AK17/AF17 -> 0.1657119 | AP17: =AL17/AG17 -> 0.083051466
A18: Total | B18: =IF(A18="Menores de 1 año",0,LEFT(A18,2)) -> To | C18: 1993 | D18: Total | E18: 45301 | F18: 23967 | G18: 21311 | H18: 23 | K18: 2001 | L18: 47848 | M18: 45480 | AA18: 50 | AB18: 62275 | AC18: 40024 | AF18: 282672.16 | AG18: 333069.24 | AJ18: 50 | AK18: 62275 | AL18: 40024 | AN18: 50 | AO18: =AK18/AF18 -> 0.22030822 | AP18: =AL18/AG18 -> 0.12016721
A19: Total | B19: =IF(A19="Menores de 1 año",0,LEFT(A19,2)) -> To | C19: 1993 | D19: 1903 | E19: 4 | F19: 3 | G19: 1 | K19: 2002 | L19: 47934 | M19: 45962 | AA19: 55 | AB19: 74606 | AC19: 53150 | AF19: 235278.02 | AG19: 281391.14 | AJ19: 55 | AK19: 74606 | AL19: 53150 | AN19: 55 | AO19: =AK19/AF19 -> 0.31709719 | AP19: =AL19/AG19 -> 0.18888299
A20: Total | B20: =IF(A20="Menores de 1 año",0,LEFT(A20,2)) -> To | C20: 1993 | D20: 1906 | E20: 1 | G20: 1 | K20: 2003 | L20: 50072 | M20: 47168 | AA20: 60 | AB20: 86957 | AC20: 68338 | AF20: 203731.67 | AG20: 253658.04 | AJ20: 60 | AK20: 86957 | AL20: 68338 | AN20: 60 | AO20: =AK20/AF20 -> 0.42682121 | AP20: =AL20/AG20 -> 0.26940995
A21: Total | B21: =IF(A21="Menores de 1 año",0,LEFT(A21,2)) -> To | C21: 1993 | D21: 1907 | E21: 1 | G21: 1 | K21: 2004 | L21: 49906 | M21: 48092 | AA21: 65 | AB21: 94843 | AC21: 82804 | AF21: 152571.32 | AG21: 193140.63 | AJ21: 65 | AK21: 94843 | AL21: 82804 | AN21: 65 | AO21: =AK21/AF21 -> 0.6216306 | AP21: =AL21/AG21 -> 0.42872388
A22: Total | B22: =IF(A22="Menores de 1 año",0,LEFT(A22,2)) -> To | C22: 1993 | D22: 1909 | E22: 1 | G22: 1 | K22: 2005 | L22: 51274 | M22: 48996 | AA22: 70 | AB22: 100787 | AC22: 95186 | AF22: 111935.03 | AG22: 148810.79 | AJ22: 70 | AK22: 100787 | AL22: 95186 | AN22: 70 | AO22: =AK22/AF22 -> 0.90040624 | AP22: =AL22/AG22 -> 0.63964447
A23: Total | B23: =IF(A23="Menores de 1 año",0,LEFT(A23,2)) -> To | C23: 1993 | D23: 1913 | E23: 4 | F23: 1 | G23: 3 | K23: 2006 | L23: 51134 | M23: 48828 | AA23: 75 | AB23: 100092 | AC23: 106789 | AF23: 72394.091 | AG23: 98970.747 | AJ23: 75 | AK23: 100092 | AL23: 106789 | AN23: 75 | AO23: =AK23/AF23 -> 1.382599 | AP23: =AL23/AG23 -> 1.0789956
A24: Total | B24: =IF(A24="Menores de 1 año",0,LEFT(A24,2)) -> To | C24: 1993 | D24: 1914 | E24: 1 | G24: 1 | K24: 2007 | L24: 52332 | M24: 50490 | AA24: 80 | AB24: 91138 | AC24: 115310 | AF24: 45013.495 | AG24: 70046.554 | AJ24: 80 | AK24: 91138 | AL24: 115310 | AN24: 80 | AO24: =AK24/AF24 -> 2.0246817 | AP24: =AL24/AG24 -> 1.6461909
A25: Total | B25: =IF(A25="Menores de 1 año",0,LEFT(A25,2)) -> To | C25: 1993 | D25: 1923 | E25: 1 | G25: 1 | K25: 2008 | L25: 53252 | M25: 51146 | AA25: 85 | AB25: 128221 | AC25: 226406 | AF25: 35718.74 | AG25: 67061.372 | AJ25: 85 | AK25: 128221 | AL25: 226406 | AN25: 85 | AO25: =AK25/AF25 -> 3.5897403 | AP25: =AL25/AG25 -> 3.3761015
A26: Total | B26: =IF(A26="Menores de 1 año",0,LEFT(A26,2)) -> To | C26: 1993 | D26: 1930 | E26: 2 | F26: 2 | K26: 2009 | L26: 54850 | M26: 52778 | AA26: No | AB26: 597 | AC26: 270
A27: Total | B27: =IF(A27="Menores de 1 año",0,LEFT(A27,2)) -> To | C27: 1993 | D27: 1933 | E27: 1 | G27: 1 | K27: 2010 | L27: 56546 | M27: 54194 | AA27: To | AB27: 1021276 | AC27: 933483
A28: Total | B28: =IF(A28="Menores de 1 año",0,LEFT(A28,2)) -> To | C28: 1993 | D28: 1943 | E28: 10 | F28: 5 | G28: 5 | K28: 2011 | L28: 56542 | M28: 52434 | AA28: Total general | AB28: 2042552 | AC28: 1866966
A29: Total | B29: =IF(A29="Menores de 1 año",0,LEFT(A29,2)) -> To | C29: 1993 | D29: 1973 | E29: 2 | G29: 2 | K29: 2012 | L29: 57782 | M29: 54288
A30: Total | B30: =IF(A30="Menores de 1 año",0,LEFT(A30,2)) -> To | C30: 1993 | D30: 1983 | E30: 4 | G30: 4 | K30: 2013 | L30: 59358 | M30: 54894
A31: Total | B31: =IF(A31="Menores de 1 año",0,LEFT(A31,2)) -> To | C31: 1993 | D31: 1990 | E31: 1 | G31: 1 | K31: 2014 | L31: 60608 | M31: 56930
A32: Total | B32: =IF(A32="Menores de 1 año",0,LEFT(A32,2)) -> To | C32: 1993 | D32: 1991 | E32: 4 | F32: 3 | G32: 1 | K32: 2015 | L32: 61008 | M32: 57732
A33: Total | B33: =IF(A33="Menores de 1 año",0,LEFT(A33,2)) -> To | C33: 1993 | D33: 1992 | E33: 192 | F33: 113 | G33: 79 | K33: 2016 | L33: 64544 | M33: 59524
A34: Total | B34: =IF(A34="Menores de 1 año",0,LEFT(A34,2)) -> To | C34: 1993 | D34: 1993 | E34: 44968 | F34: 23752 | G34: 21193 | H34: 23 | K34: 2017 | L34: 63778 | M34: 60292
A35: Total | B35: =IF(A35="Menores de 1 año",0,LEFT(A35,2)) -> To | C35: 1993 | D35: No especificado | E35: 104 | F35: 88 | G35: 16 | K35: 2018 | L35: 65246 | M35: 61242
A36: Total | B36: =IF(A36="Menores de 1 año",0,LEFT(A36,2)) -> To | C36: 1994 | D36: Total | E36: 45686 | F36: 24149 | G36: 21516 | H36: 21 | K36: 2019 | L36: 66008 | M36: 60594
A37: Total | B37: =IF(A37="Menores de 1 año",0,LEFT(A37,2)) -> To | C37: 1994 | D37: 1903 | E37: 1 | F37: 1 | K37: 2020 | L37: 124244 | M37: 90862
A38: Total | B38: =IF(A38="Menores de 1 año",0,LEFT(A38,2)) -> To | C38: 1994 | D38: 1904 | E38: 6 | F38: 3 | G38: 3 | K38: 2021 | L38: 110904 | M38: 89130
A39: Total | B39: =IF(A39="Menores de 1 año",0,LEFT(A39,2)) -> To | C39: 1994 | D39: 1910 | E39: 2 | F39: 1 | G39: 1 | K39: 2022 | L39: 71394 | M39: 67256
A40: Total | B40: =IF(A40="Menores de 1 año",0,LEFT(A40,2)) -> To | C40: 1994 | D40: 1911 | E40: 1 | G40: 1 | K40: 2023 | L40: 67144 | M40: 63466
A41: Total | B41: =IF(A41="Menores de 1 año",0,LEFT(A41,2)) -> To | C41: 1994 | D41: 1940 | E41: 1 | F41: 1 | K41: 2024 | L41: 68914 | M41: 64708
...
